Internal Server Error: /osamosvojitev
Traceback (most recent call last):
  File "/home/parladaddy/parlasearch/venv/local/lib/python2.7/site-packages/django/core/handlers/base.py", line 108, in get_response
    response = middleware_method(request)
  File "/home/parladaddy/parlasearch/venv/local/lib/python2.7/site-packages/django/middleware/common.py", line 74, in process_request
    if (not urlresolvers.is_valid_path(request.path_info, urlconf) and
  File "/home/parladaddy/parlasearch/venv/local/lib/python2.7/site-packages/django/core/urlresolvers.py", line 646, in is_valid_path
    resolve(path, urlconf)
  File "/home/parladaddy/parlasearch/venv/local/lib/python2.7/site-packages/django/core/urlresolvers.py", line 521, in resolve
    return get_resolver(urlconf).resolve(path)
  File "/home/parladaddy/parlasearch/venv/local/lib/python2.7/site-packages/django/core/urlresolvers.py", line 365, in resolve
    for pattern in self.url_patterns:
  File "/home/parladaddy/parlasearch/venv/local/lib/python2.7/site-packages/django/core/urlresolvers.py", line 401, in url_patterns
    patterns = getattr(self.urlconf_module, "urlpatterns", self.urlconf_module)
  File "/home/parladaddy/parlasearch/venv/local/lib/python2.7/site-packages/django/core/urlresolvers.py", line 395, in urlconf_module
    self._urlconf_module = import_module(self.urlconf_name)
  File "/usr/lib/python2.7/importlib/__init__.py", line 37, in import_module
    __import__(name)
  File "/home/parladaddy/parlasearch/parlasearch/urls.py", line 21, in <module>
    url(r'^?P<person_id>[a-z A-Z 0-9 \ -]+', parlasearch.views.query),
NameError: name 'parlasearch' is not defined
Internal Server Error: /osamosvojitev
Traceback (most recent call last):
  File "/home/parladaddy/parlasearch/venv/local/lib/python2.7/site-packages/django/core/handlers/base.py", line 108, in get_response
    response = middleware_method(request)
  File "/home/parladaddy/parlasearch/venv/local/lib/python2.7/site-packages/django/middleware/common.py", line 74, in process_request
    if (not urlresolvers.is_valid_path(request.path_info, urlconf) and
  File "/home/parladaddy/parlasearch/venv/local/lib/python2.7/site-packages/django/core/urlresolvers.py", line 646, in is_valid_path
    resolve(path, urlconf)
  File "/home/parladaddy/parlasearch/venv/local/lib/python2.7/site-packages/django/core/urlresolvers.py", line 521, in resolve
    return get_resolver(urlconf).resolve(path)
  File "/home/parladaddy/parlasearch/venv/local/lib/python2.7/site-packages/django/core/urlresolvers.py", line 365, in resolve
    for pattern in self.url_patterns:
  File "/home/parladaddy/parlasearch/venv/local/lib/python2.7/site-packages/django/core/urlresolvers.py", line 401, in url_patterns
    patterns = getattr(self.urlconf_module, "urlpatterns", self.urlconf_module)
  File "/home/parladaddy/parlasearch/venv/local/lib/python2.7/site-packages/django/core/urlresolvers.py", line 395, in urlconf_module
    self._urlconf_module = import_module(self.urlconf_name)
  File "/usr/lib/python2.7/importlib/__init__.py", line 37, in import_module
    __import__(name)
  File "/home/parladaddy/parlasearch/parlasearch/urls.py", line 21, in <module>
    url(r'^?P<person_id>[a-z A-Z 0-9 \ -]+', searchapi.views.query),
NameError: name 'searchapi' is not defined
Internal Server Error: /osamosvojitev
Traceback (most recent call last):
  File "/home/parladaddy/parlasearch/venv/local/lib/python2.7/site-packages/django/core/handlers/base.py", line 108, in get_response
    response = middleware_method(request)
  File "/home/parladaddy/parlasearch/venv/local/lib/python2.7/site-packages/django/middleware/common.py", line 74, in process_request
    if (not urlresolvers.is_valid_path(request.path_info, urlconf) and
  File "/home/parladaddy/parlasearch/venv/local/lib/python2.7/site-packages/django/core/urlresolvers.py", line 646, in is_valid_path
    resolve(path, urlconf)
  File "/home/parladaddy/parlasearch/venv/local/lib/python2.7/site-packages/django/core/urlresolvers.py", line 521, in resolve
    return get_resolver(urlconf).resolve(path)
  File "/home/parladaddy/parlasearch/venv/local/lib/python2.7/site-packages/django/core/urlresolvers.py", line 365, in resolve
    for pattern in self.url_patterns:
  File "/home/parladaddy/parlasearch/venv/local/lib/python2.7/site-packages/django/core/urlresolvers.py", line 401, in url_patterns
    patterns = getattr(self.urlconf_module, "urlpatterns", self.urlconf_module)
  File "/home/parladaddy/parlasearch/venv/local/lib/python2.7/site-packages/django/core/urlresolvers.py", line 395, in urlconf_module
    self._urlconf_module = import_module(self.urlconf_name)
  File "/usr/lib/python2.7/importlib/__init__.py", line 37, in import_module
    __import__(name)
  File "/home/parladaddy/parlasearch/parlasearch/urls.py", line 21, in <module>
    url(r'^?P<person_id>[a-z A-Z 0-9 \ -]+', searchapi.views.query),
NameError: name 'searchapi' is not defined
Internal Server Error: /osamosvojitev
Traceback (most recent call last):
  File "/home/parladaddy/parlasearch/venv/local/lib/python2.7/site-packages/django/core/handlers/base.py", line 108, in get_response
    response = middleware_method(request)
  File "/home/parladaddy/parlasearch/venv/local/lib/python2.7/site-packages/django/middleware/common.py", line 74, in process_request
    if (not urlresolvers.is_valid_path(request.path_info, urlconf) and
  File "/home/parladaddy/parlasearch/venv/local/lib/python2.7/site-packages/django/core/urlresolvers.py", line 646, in is_valid_path
    resolve(path, urlconf)
  File "/home/parladaddy/parlasearch/venv/local/lib/python2.7/site-packages/django/core/urlresolvers.py", line 521, in resolve
    return get_resolver(urlconf).resolve(path)
  File "/home/parladaddy/parlasearch/venv/local/lib/python2.7/site-packages/django/core/urlresolvers.py", line 367, in resolve
    sub_match = pattern.resolve(new_path)
  File "/home/parladaddy/parlasearch/venv/local/lib/python2.7/site-packages/django/core/urlresolvers.py", line 226, in resolve
    match = self.regex.search(path)
  File "/home/parladaddy/parlasearch/venv/local/lib/python2.7/site-packages/django/core/urlresolvers.py", line 194, in regex
    (regex, six.text_type(e)))
ImproperlyConfigured: "^?P<person_id>[a-z A-Z 0-9 \ -]+" is not a valid regular expression: nothing to repeat
Internal Server Error: /osamosvojitev
Traceback (most recent call last):
  File "/home/parladaddy/parlasearch/venv/local/lib/python2.7/site-packages/django/core/handlers/base.py", line 108, in get_response
    response = middleware_method(request)
  File "/home/parladaddy/parlasearch/venv/local/lib/python2.7/site-packages/django/middleware/common.py", line 74, in process_request
    if (not urlresolvers.is_valid_path(request.path_info, urlconf) and
  File "/home/parladaddy/parlasearch/venv/local/lib/python2.7/site-packages/django/core/urlresolvers.py", line 646, in is_valid_path
    resolve(path, urlconf)
  File "/home/parladaddy/parlasearch/venv/local/lib/python2.7/site-packages/django/core/urlresolvers.py", line 521, in resolve
    return get_resolver(urlconf).resolve(path)
  File "/home/parladaddy/parlasearch/venv/local/lib/python2.7/site-packages/django/core/urlresolvers.py", line 367, in resolve
    sub_match = pattern.resolve(new_path)
  File "/home/parladaddy/parlasearch/venv/local/lib/python2.7/site-packages/django/core/urlresolvers.py", line 226, in resolve
    match = self.regex.search(path)
  File "/home/parladaddy/parlasearch/venv/local/lib/python2.7/site-packages/django/core/urlresolvers.py", line 194, in regex
    (regex, six.text_type(e)))
ImproperlyConfigured: "^?P<person_id>([a-z A-Z 0-9 \ -])+" is not a valid regular expression: nothing to repeat
Internal Server Error: /osamosvojitev
Traceback (most recent call last):
  File "/home/parladaddy/parlasearch/venv/local/lib/python2.7/site-packages/django/core/handlers/base.py", line 108, in get_response
    response = middleware_method(request)
  File "/home/parladaddy/parlasearch/venv/local/lib/python2.7/site-packages/django/middleware/common.py", line 74, in process_request
    if (not urlresolvers.is_valid_path(request.path_info, urlconf) and
  File "/home/parladaddy/parlasearch/venv/local/lib/python2.7/site-packages/django/core/urlresolvers.py", line 646, in is_valid_path
    resolve(path, urlconf)
  File "/home/parladaddy/parlasearch/venv/local/lib/python2.7/site-packages/django/core/urlresolvers.py", line 521, in resolve
    return get_resolver(urlconf).resolve(path)
  File "/home/parladaddy/parlasearch/venv/local/lib/python2.7/site-packages/django/core/urlresolvers.py", line 367, in resolve
    sub_match = pattern.resolve(new_path)
  File "/home/parladaddy/parlasearch/venv/local/lib/python2.7/site-packages/django/core/urlresolvers.py", line 226, in resolve
    match = self.regex.search(path)
  File "/home/parladaddy/parlasearch/venv/local/lib/python2.7/site-packages/django/core/urlresolvers.py", line 194, in regex
    (regex, six.text_type(e)))
ImproperlyConfigured: "^?P<person_id>([a-z A-Z 0-9 \ -])+" is not a valid regular expression: nothing to repeat
Internal Server Error: /osamosvojitev
Traceback (most recent call last):
  File "/home/parladaddy/parlasearch/venv/local/lib/python2.7/site-packages/django/core/handlers/base.py", line 108, in get_response
    response = middleware_method(request)
  File "/home/parladaddy/parlasearch/venv/local/lib/python2.7/site-packages/django/middleware/common.py", line 74, in process_request
    if (not urlresolvers.is_valid_path(request.path_info, urlconf) and
  File "/home/parladaddy/parlasearch/venv/local/lib/python2.7/site-packages/django/core/urlresolvers.py", line 646, in is_valid_path
    resolve(path, urlconf)
  File "/home/parladaddy/parlasearch/venv/local/lib/python2.7/site-packages/django/core/urlresolvers.py", line 521, in resolve
    return get_resolver(urlconf).resolve(path)
  File "/home/parladaddy/parlasearch/venv/local/lib/python2.7/site-packages/django/core/urlresolvers.py", line 367, in resolve
    sub_match = pattern.resolve(new_path)
  File "/home/parladaddy/parlasearch/venv/local/lib/python2.7/site-packages/django/core/urlresolvers.py", line 226, in resolve
    match = self.regex.search(path)
  File "/home/parladaddy/parlasearch/venv/local/lib/python2.7/site-packages/django/core/urlresolvers.py", line 194, in regex
    (regex, six.text_type(e)))
ImproperlyConfigured: "^?P<person_id>([a-z A-Z 0-9 \ -]+)" is not a valid regular expression: nothing to repeat
Internal Server Error: /osamosvojitev
Traceback (most recent call last):
  File "/home/parladaddy/parlasearch/venv/local/lib/python2.7/site-packages/django/core/handlers/base.py", line 108, in get_response
    response = middleware_method(request)
  File "/home/parladaddy/parlasearch/venv/local/lib/python2.7/site-packages/django/middleware/common.py", line 74, in process_request
    if (not urlresolvers.is_valid_path(request.path_info, urlconf) and
  File "/home/parladaddy/parlasearch/venv/local/lib/python2.7/site-packages/django/core/urlresolvers.py", line 646, in is_valid_path
    resolve(path, urlconf)
  File "/home/parladaddy/parlasearch/venv/local/lib/python2.7/site-packages/django/core/urlresolvers.py", line 521, in resolve
    return get_resolver(urlconf).resolve(path)
  File "/home/parladaddy/parlasearch/venv/local/lib/python2.7/site-packages/django/core/urlresolvers.py", line 367, in resolve
    sub_match = pattern.resolve(new_path)
  File "/home/parladaddy/parlasearch/venv/local/lib/python2.7/site-packages/django/core/urlresolvers.py", line 226, in resolve
    match = self.regex.search(path)
  File "/home/parladaddy/parlasearch/venv/local/lib/python2.7/site-packages/django/core/urlresolvers.py", line 194, in regex
    (regex, six.text_type(e)))
ImproperlyConfigured: "^?P<person_id>([a-z A-Z 0-9 -]+)" is not a valid regular expression: nothing to repeat
Internal Server Error: /osamosvojitev
Traceback (most recent call last):
  File "/home/parladaddy/parlasearch/venv/local/lib/python2.7/site-packages/django/core/handlers/base.py", line 108, in get_response
    response = middleware_method(request)
  File "/home/parladaddy/parlasearch/venv/local/lib/python2.7/site-packages/django/middleware/common.py", line 74, in process_request
    if (not urlresolvers.is_valid_path(request.path_info, urlconf) and
  File "/home/parladaddy/parlasearch/venv/local/lib/python2.7/site-packages/django/core/urlresolvers.py", line 646, in is_valid_path
    resolve(path, urlconf)
  File "/home/parladaddy/parlasearch/venv/local/lib/python2.7/site-packages/django/core/urlresolvers.py", line 521, in resolve
    return get_resolver(urlconf).resolve(path)
  File "/home/parladaddy/parlasearch/venv/local/lib/python2.7/site-packages/django/core/urlresolvers.py", line 367, in resolve
    sub_match = pattern.resolve(new_path)
  File "/home/parladaddy/parlasearch/venv/local/lib/python2.7/site-packages/django/core/urlresolvers.py", line 226, in resolve
    match = self.regex.search(path)
  File "/home/parladaddy/parlasearch/venv/local/lib/python2.7/site-packages/django/core/urlresolvers.py", line 194, in regex
    (regex, six.text_type(e)))
ImproperlyConfigured: "^?P<person_id>([a-z A-Z 0-9 -]+)" is not a valid regular expression: nothing to repeat
Internal Server Error: /osamosvojitev
Traceback (most recent call last):
  File "/home/parladaddy/parlasearch/venv/local/lib/python2.7/site-packages/django/core/handlers/base.py", line 108, in get_response
    response = middleware_method(request)
  File "/home/parladaddy/parlasearch/venv/local/lib/python2.7/site-packages/django/middleware/common.py", line 74, in process_request
    if (not urlresolvers.is_valid_path(request.path_info, urlconf) and
  File "/home/parladaddy/parlasearch/venv/local/lib/python2.7/site-packages/django/core/urlresolvers.py", line 646, in is_valid_path
    resolve(path, urlconf)
  File "/home/parladaddy/parlasearch/venv/local/lib/python2.7/site-packages/django/core/urlresolvers.py", line 521, in resolve
    return get_resolver(urlconf).resolve(path)
  File "/home/parladaddy/parlasearch/venv/local/lib/python2.7/site-packages/django/core/urlresolvers.py", line 367, in resolve
    sub_match = pattern.resolve(new_path)
  File "/home/parladaddy/parlasearch/venv/local/lib/python2.7/site-packages/django/core/urlresolvers.py", line 226, in resolve
    match = self.regex.search(path)
  File "/home/parladaddy/parlasearch/venv/local/lib/python2.7/site-packages/django/core/urlresolvers.py", line 194, in regex
    (regex, six.text_type(e)))
ImproperlyConfigured: "^?P<person_id>([a-zA-Z0-9- ]+)" is not a valid regular expression: nothing to repeat
Internal Server Error: /osamosvojitev
Traceback (most recent call last):
  File "/home/parladaddy/parlasearch/venv/local/lib/python2.7/site-packages/django/core/handlers/base.py", line 108, in get_response
    response = middleware_method(request)
  File "/home/parladaddy/parlasearch/venv/local/lib/python2.7/site-packages/django/middleware/common.py", line 74, in process_request
    if (not urlresolvers.is_valid_path(request.path_info, urlconf) and
  File "/home/parladaddy/parlasearch/venv/local/lib/python2.7/site-packages/django/core/urlresolvers.py", line 646, in is_valid_path
    resolve(path, urlconf)
  File "/home/parladaddy/parlasearch/venv/local/lib/python2.7/site-packages/django/core/urlresolvers.py", line 521, in resolve
    return get_resolver(urlconf).resolve(path)
  File "/home/parladaddy/parlasearch/venv/local/lib/python2.7/site-packages/django/core/urlresolvers.py", line 367, in resolve
    sub_match = pattern.resolve(new_path)
  File "/home/parladaddy/parlasearch/venv/local/lib/python2.7/site-packages/django/core/urlresolvers.py", line 226, in resolve
    match = self.regex.search(path)
  File "/home/parladaddy/parlasearch/venv/local/lib/python2.7/site-packages/django/core/urlresolvers.py", line 194, in regex
    (regex, six.text_type(e)))
ImproperlyConfigured: "^?P<person_id>([a-zA-Z0-9\-]+)" is not a valid regular expression: nothing to repeat
Internal Server Error: /osamosvojitev
Traceback (most recent call last):
  File "/home/parladaddy/parlasearch/venv/local/lib/python2.7/site-packages/django/core/handlers/base.py", line 108, in get_response
    response = middleware_method(request)
  File "/home/parladaddy/parlasearch/venv/local/lib/python2.7/site-packages/django/middleware/common.py", line 74, in process_request
    if (not urlresolvers.is_valid_path(request.path_info, urlconf) and
  File "/home/parladaddy/parlasearch/venv/local/lib/python2.7/site-packages/django/core/urlresolvers.py", line 646, in is_valid_path
    resolve(path, urlconf)
  File "/home/parladaddy/parlasearch/venv/local/lib/python2.7/site-packages/django/core/urlresolvers.py", line 521, in resolve
    return get_resolver(urlconf).resolve(path)
  File "/home/parladaddy/parlasearch/venv/local/lib/python2.7/site-packages/django/core/urlresolvers.py", line 367, in resolve
    sub_match = pattern.resolve(new_path)
  File "/home/parladaddy/parlasearch/venv/local/lib/python2.7/site-packages/django/core/urlresolvers.py", line 226, in resolve
    match = self.regex.search(path)
  File "/home/parladaddy/parlasearch/venv/local/lib/python2.7/site-packages/django/core/urlresolvers.py", line 194, in regex
    (regex, six.text_type(e)))
ImproperlyConfigured: "^?P<person_id>([a-zA-Z0-9]+)" is not a valid regular expression: nothing to repeat
Internal Server Error: /osamosvojitev
Traceback (most recent call last):
  File "/home/parladaddy/parlasearch/venv/local/lib/python2.7/site-packages/django/core/handlers/base.py", line 108, in get_response
    response = middleware_method(request)
  File "/home/parladaddy/parlasearch/venv/local/lib/python2.7/site-packages/django/middleware/common.py", line 74, in process_request
    if (not urlresolvers.is_valid_path(request.path_info, urlconf) and
  File "/home/parladaddy/parlasearch/venv/local/lib/python2.7/site-packages/django/core/urlresolvers.py", line 646, in is_valid_path
    resolve(path, urlconf)
  File "/home/parladaddy/parlasearch/venv/local/lib/python2.7/site-packages/django/core/urlresolvers.py", line 521, in resolve
    return get_resolver(urlconf).resolve(path)
  File "/home/parladaddy/parlasearch/venv/local/lib/python2.7/site-packages/django/core/urlresolvers.py", line 367, in resolve
    sub_match = pattern.resolve(new_path)
  File "/home/parladaddy/parlasearch/venv/local/lib/python2.7/site-packages/django/core/urlresolvers.py", line 226, in resolve
    match = self.regex.search(path)
  File "/home/parladaddy/parlasearch/venv/local/lib/python2.7/site-packages/django/core/urlresolvers.py", line 194, in regex
    (regex, six.text_type(e)))
ImproperlyConfigured: "^?P<person_id>(\w+)" is not a valid regular expression: nothing to repeat
Internal Server Error: /osamosvojitev
Traceback (most recent call last):
  File "/home/parladaddy/parlasearch/venv/local/lib/python2.7/site-packages/django/core/handlers/base.py", line 108, in get_response
    response = middleware_method(request)
  File "/home/parladaddy/parlasearch/venv/local/lib/python2.7/site-packages/django/middleware/common.py", line 74, in process_request
    if (not urlresolvers.is_valid_path(request.path_info, urlconf) and
  File "/home/parladaddy/parlasearch/venv/local/lib/python2.7/site-packages/django/core/urlresolvers.py", line 646, in is_valid_path
    resolve(path, urlconf)
  File "/home/parladaddy/parlasearch/venv/local/lib/python2.7/site-packages/django/core/urlresolvers.py", line 521, in resolve
    return get_resolver(urlconf).resolve(path)
  File "/home/parladaddy/parlasearch/venv/local/lib/python2.7/site-packages/django/core/urlresolvers.py", line 367, in resolve
    sub_match = pattern.resolve(new_path)
  File "/home/parladaddy/parlasearch/venv/local/lib/python2.7/site-packages/django/core/urlresolvers.py", line 226, in resolve
    match = self.regex.search(path)
  File "/home/parladaddy/parlasearch/venv/local/lib/python2.7/site-packages/django/core/urlresolvers.py", line 194, in regex
    (regex, six.text_type(e)))
ImproperlyConfigured: "^?P<person_id>\w+" is not a valid regular expression: nothing to repeat
Not Found: /osamosvojitev
Internal Server Error: /osamosvojitev
Traceback (most recent call last):
  File "/home/parladaddy/parlasearch/venv/local/lib/python2.7/site-packages/django/core/handlers/base.py", line 132, in get_response
    response = wrapped_callback(request, *callback_args, **callback_kwargs)
TypeError: query() got an unexpected keyword argument 'person_id'
Not Found: /
Internal Server Error: /osamosvojitev
Traceback (most recent call last):
  File "/home/parladaddy/parlasearch/venv/local/lib/python2.7/site-packages/django/core/handlers/base.py", line 108, in get_response
    response = middleware_method(request)
  File "/home/parladaddy/parlasearch/venv/local/lib/python2.7/site-packages/django/middleware/common.py", line 74, in process_request
    if (not urlresolvers.is_valid_path(request.path_info, urlconf) and
  File "/home/parladaddy/parlasearch/venv/local/lib/python2.7/site-packages/django/core/urlresolvers.py", line 646, in is_valid_path
    resolve(path, urlconf)
  File "/home/parladaddy/parlasearch/venv/local/lib/python2.7/site-packages/django/core/urlresolvers.py", line 521, in resolve
    return get_resolver(urlconf).resolve(path)
  File "/home/parladaddy/parlasearch/venv/local/lib/python2.7/site-packages/django/core/urlresolvers.py", line 365, in resolve
    for pattern in self.url_patterns:
  File "/home/parladaddy/parlasearch/venv/local/lib/python2.7/site-packages/django/core/urlresolvers.py", line 401, in url_patterns
    patterns = getattr(self.urlconf_module, "urlpatterns", self.urlconf_module)
  File "/home/parladaddy/parlasearch/venv/local/lib/python2.7/site-packages/django/core/urlresolvers.py", line 395, in urlconf_module
    self._urlconf_module = import_module(self.urlconf_name)
  File "/usr/lib/python2.7/importlib/__init__.py", line 37, in import_module
    __import__(name)
  File "/home/parladaddy/parlasearch/parlasearch/urls.py", line 18, in <module>
    from searchapi.views import query
  File "/home/parladaddy/parlasearch/searchapi/views.py", line 9
    'q': 'content_t',
      ^
SyntaxError: invalid syntax
Internal Server Error: /favicon.ico
Traceback (most recent call last):
  File "/home/parladaddy/parlasearch/venv/local/lib/python2.7/site-packages/django/core/handlers/base.py", line 108, in get_response
    response = middleware_method(request)
  File "/home/parladaddy/parlasearch/venv/local/lib/python2.7/site-packages/django/middleware/common.py", line 74, in process_request
    if (not urlresolvers.is_valid_path(request.path_info, urlconf) and
  File "/home/parladaddy/parlasearch/venv/local/lib/python2.7/site-packages/django/core/urlresolvers.py", line 646, in is_valid_path
    resolve(path, urlconf)
  File "/home/parladaddy/parlasearch/venv/local/lib/python2.7/site-packages/django/core/urlresolvers.py", line 521, in resolve
    return get_resolver(urlconf).resolve(path)
  File "/home/parladaddy/parlasearch/venv/local/lib/python2.7/site-packages/django/core/urlresolvers.py", line 365, in resolve
    for pattern in self.url_patterns:
  File "/home/parladaddy/parlasearch/venv/local/lib/python2.7/site-packages/django/core/urlresolvers.py", line 401, in url_patterns
    patterns = getattr(self.urlconf_module, "urlpatterns", self.urlconf_module)
  File "/home/parladaddy/parlasearch/venv/local/lib/python2.7/site-packages/django/core/urlresolvers.py", line 395, in urlconf_module
    self._urlconf_module = import_module(self.urlconf_name)
  File "/usr/lib/python2.7/importlib/__init__.py", line 37, in import_module
    __import__(name)
  File "/home/parladaddy/parlasearch/parlasearch/urls.py", line 18, in <module>
    from searchapi.views import query
  File "/home/parladaddy/parlasearch/searchapi/views.py", line 9
    'q': 'content_t',
      ^
SyntaxError: invalid syntax
Internal Server Error: /osamosvojitev
Traceback (most recent call last):
  File "/home/parladaddy/parlasearch/venv/local/lib/python2.7/site-packages/django/core/handlers/base.py", line 108, in get_response
    response = middleware_method(request)
  File "/home/parladaddy/parlasearch/venv/local/lib/python2.7/site-packages/django/middleware/common.py", line 74, in process_request
    if (not urlresolvers.is_valid_path(request.path_info, urlconf) and
  File "/home/parladaddy/parlasearch/venv/local/lib/python2.7/site-packages/django/core/urlresolvers.py", line 646, in is_valid_path
    resolve(path, urlconf)
  File "/home/parladaddy/parlasearch/venv/local/lib/python2.7/site-packages/django/core/urlresolvers.py", line 521, in resolve
    return get_resolver(urlconf).resolve(path)
  File "/home/parladaddy/parlasearch/venv/local/lib/python2.7/site-packages/django/core/urlresolvers.py", line 365, in resolve
    for pattern in self.url_patterns:
  File "/home/parladaddy/parlasearch/venv/local/lib/python2.7/site-packages/django/core/urlresolvers.py", line 401, in url_patterns
    patterns = getattr(self.urlconf_module, "urlpatterns", self.urlconf_module)
  File "/home/parladaddy/parlasearch/venv/local/lib/python2.7/site-packages/django/core/urlresolvers.py", line 395, in urlconf_module
    self._urlconf_module = import_module(self.urlconf_name)
  File "/usr/lib/python2.7/importlib/__init__.py", line 37, in import_module
    __import__(name)
  File "/home/parladaddy/parlasearch/parlasearch/urls.py", line 18, in <module>
    from searchapi.views import query
  File "/home/parladaddy/parlasearch/searchapi/views.py", line 9
    'q': 'content_t',
      ^
SyntaxError: invalid syntax
Internal Server Error: /favicon.ico
Traceback (most recent call last):
  File "/home/parladaddy/parlasearch/venv/local/lib/python2.7/site-packages/django/core/handlers/base.py", line 108, in get_response
    response = middleware_method(request)
  File "/home/parladaddy/parlasearch/venv/local/lib/python2.7/site-packages/django/middleware/common.py", line 74, in process_request
    if (not urlresolvers.is_valid_path(request.path_info, urlconf) and
  File "/home/parladaddy/parlasearch/venv/local/lib/python2.7/site-packages/django/core/urlresolvers.py", line 646, in is_valid_path
    resolve(path, urlconf)
  File "/home/parladaddy/parlasearch/venv/local/lib/python2.7/site-packages/django/core/urlresolvers.py", line 521, in resolve
    return get_resolver(urlconf).resolve(path)
  File "/home/parladaddy/parlasearch/venv/local/lib/python2.7/site-packages/django/core/urlresolvers.py", line 365, in resolve
    for pattern in self.url_patterns:
  File "/home/parladaddy/parlasearch/venv/local/lib/python2.7/site-packages/django/core/urlresolvers.py", line 401, in url_patterns
    patterns = getattr(self.urlconf_module, "urlpatterns", self.urlconf_module)
  File "/home/parladaddy/parlasearch/venv/local/lib/python2.7/site-packages/django/core/urlresolvers.py", line 395, in urlconf_module
    self._urlconf_module = import_module(self.urlconf_name)
  File "/usr/lib/python2.7/importlib/__init__.py", line 37, in import_module
    __import__(name)
  File "/home/parladaddy/parlasearch/parlasearch/urls.py", line 18, in <module>
    from searchapi.views import query
  File "/home/parladaddy/parlasearch/searchapi/views.py", line 9
    'q': 'content_t',
      ^
SyntaxError: invalid syntax
Internal Server Error: /osamosvojitev
Traceback (most recent call last):
  File "/home/parladaddy/parlasearch/venv/local/lib/python2.7/site-packages/django/core/handlers/base.py", line 108, in get_response
    response = middleware_method(request)
  File "/home/parladaddy/parlasearch/venv/local/lib/python2.7/site-packages/django/middleware/common.py", line 74, in process_request
    if (not urlresolvers.is_valid_path(request.path_info, urlconf) and
  File "/home/parladaddy/parlasearch/venv/local/lib/python2.7/site-packages/django/core/urlresolvers.py", line 646, in is_valid_path
    resolve(path, urlconf)
  File "/home/parladaddy/parlasearch/venv/local/lib/python2.7/site-packages/django/core/urlresolvers.py", line 521, in resolve
    return get_resolver(urlconf).resolve(path)
  File "/home/parladaddy/parlasearch/venv/local/lib/python2.7/site-packages/django/core/urlresolvers.py", line 365, in resolve
    for pattern in self.url_patterns:
  File "/home/parladaddy/parlasearch/venv/local/lib/python2.7/site-packages/django/core/urlresolvers.py", line 401, in url_patterns
    patterns = getattr(self.urlconf_module, "urlpatterns", self.urlconf_module)
  File "/home/parladaddy/parlasearch/venv/local/lib/python2.7/site-packages/django/core/urlresolvers.py", line 395, in urlconf_module
    self._urlconf_module = import_module(self.urlconf_name)
  File "/usr/lib/python2.7/importlib/__init__.py", line 37, in import_module
    __import__(name)
  File "/home/parladaddy/parlasearch/parlasearch/urls.py", line 18, in <module>
    from searchapi.views import query
  File "/home/parladaddy/parlasearch/searchapi/views.py", line 9
    'q': 'content_t',
      ^
SyntaxError: invalid syntax
Internal Server Error: /favicon.ico
Traceback (most recent call last):
  File "/home/parladaddy/parlasearch/venv/local/lib/python2.7/site-packages/django/core/handlers/base.py", line 108, in get_response
    response = middleware_method(request)
  File "/home/parladaddy/parlasearch/venv/local/lib/python2.7/site-packages/django/middleware/common.py", line 74, in process_request
    if (not urlresolvers.is_valid_path(request.path_info, urlconf) and
  File "/home/parladaddy/parlasearch/venv/local/lib/python2.7/site-packages/django/core/urlresolvers.py", line 646, in is_valid_path
    resolve(path, urlconf)
  File "/home/parladaddy/parlasearch/venv/local/lib/python2.7/site-packages/django/core/urlresolvers.py", line 521, in resolve
    return get_resolver(urlconf).resolve(path)
  File "/home/parladaddy/parlasearch/venv/local/lib/python2.7/site-packages/django/core/urlresolvers.py", line 365, in resolve
    for pattern in self.url_patterns:
  File "/home/parladaddy/parlasearch/venv/local/lib/python2.7/site-packages/django/core/urlresolvers.py", line 401, in url_patterns
    patterns = getattr(self.urlconf_module, "urlpatterns", self.urlconf_module)
  File "/home/parladaddy/parlasearch/venv/local/lib/python2.7/site-packages/django/core/urlresolvers.py", line 395, in urlconf_module
    self._urlconf_module = import_module(self.urlconf_name)
  File "/usr/lib/python2.7/importlib/__init__.py", line 37, in import_module
    __import__(name)
  File "/home/parladaddy/parlasearch/parlasearch/urls.py", line 18, in <module>
    from searchapi.views import query
  File "/home/parladaddy/parlasearch/searchapi/views.py", line 9
    'q': 'content_t',
      ^
SyntaxError: invalid syntax
Internal Server Error: /osamosvojitev
Traceback (most recent call last):
  File "/home/parladaddy/parlasearch/venv/local/lib/python2.7/site-packages/django/core/handlers/base.py", line 132, in get_response
    response = wrapped_callback(request, *callback_args, **callback_kwargs)
  File "/home/parladaddy/parlasearch/searchapi/views.py", line 28, in query
    url = solr_url
UnboundLocalError: local variable 'solr_url' referenced before assignment
Internal Server Error: /favicon.ico
Traceback (most recent call last):
  File "/home/parladaddy/parlasearch/venv/local/lib/python2.7/site-packages/django/core/handlers/base.py", line 132, in get_response
    response = wrapped_callback(request, *callback_args, **callback_kwargs)
  File "/home/parladaddy/parlasearch/searchapi/views.py", line 28, in query
    url = solr_url
UnboundLocalError: local variable 'solr_url' referenced before assignment
Not Found: /"osamosvojitev je bila"
Not Found: /
Not Found: /
Internal Server Error: /filter/kriza/11 12/5 6 7/
Traceback (most recent call last):
  File "/home/parladaddy/parlasearch/venv/local/lib/python2.7/site-packages/django/core/handlers/base.py", line 119, in get_response
    resolver_match = resolver.resolve(request.path_info)
  File "/home/parladaddy/parlasearch/venv/local/lib/python2.7/site-packages/django/core/urlresolvers.py", line 365, in resolve
    for pattern in self.url_patterns:
  File "/home/parladaddy/parlasearch/venv/local/lib/python2.7/site-packages/django/core/urlresolvers.py", line 401, in url_patterns
    patterns = getattr(self.urlconf_module, "urlpatterns", self.urlconf_module)
  File "/home/parladaddy/parlasearch/venv/local/lib/python2.7/site-packages/django/core/urlresolvers.py", line 395, in urlconf_module
    self._urlconf_module = import_module(self.urlconf_name)
  File "/usr/lib/python2.7/importlib/__init__.py", line 37, in import_module
    __import__(name)
  File "/home/parladaddy/parlasearch/parlasearch/urls.py", line 18, in <module>
    from searchapi.views import query
  File "/home/parladaddy/parlasearch/searchapi/views.py", line 50
    'fq': 'speaker_i:(' + people + ') OR party_i:(' + parties ')',
                                                                ^
SyntaxError: invalid syntax
Internal Server Error: /favicon.ico
Traceback (most recent call last):
  File "/home/parladaddy/parlasearch/venv/local/lib/python2.7/site-packages/django/core/handlers/base.py", line 108, in get_response
    response = middleware_method(request)
  File "/home/parladaddy/parlasearch/venv/local/lib/python2.7/site-packages/django/middleware/common.py", line 74, in process_request
    if (not urlresolvers.is_valid_path(request.path_info, urlconf) and
  File "/home/parladaddy/parlasearch/venv/local/lib/python2.7/site-packages/django/core/urlresolvers.py", line 646, in is_valid_path
    resolve(path, urlconf)
  File "/home/parladaddy/parlasearch/venv/local/lib/python2.7/site-packages/django/core/urlresolvers.py", line 521, in resolve
    return get_resolver(urlconf).resolve(path)
  File "/home/parladaddy/parlasearch/venv/local/lib/python2.7/site-packages/django/core/urlresolvers.py", line 365, in resolve
    for pattern in self.url_patterns:
  File "/home/parladaddy/parlasearch/venv/local/lib/python2.7/site-packages/django/core/urlresolvers.py", line 401, in url_patterns
    patterns = getattr(self.urlconf_module, "urlpatterns", self.urlconf_module)
  File "/home/parladaddy/parlasearch/venv/local/lib/python2.7/site-packages/django/core/urlresolvers.py", line 395, in urlconf_module
    self._urlconf_module = import_module(self.urlconf_name)
  File "/usr/lib/python2.7/importlib/__init__.py", line 37, in import_module
    __import__(name)
  File "/home/parladaddy/parlasearch/parlasearch/urls.py", line 18, in <module>
    from searchapi.views import query
  File "/home/parladaddy/parlasearch/searchapi/views.py", line 50
    'fq': 'speaker_i:(' + people + ') OR party_i:(' + parties ')',
                                                                ^
SyntaxError: invalid syntax
Internal Server Error: /filter/kriza/11 12/5 6 7
Traceback (most recent call last):
  File "/home/parladaddy/parlasearch/venv/local/lib/python2.7/site-packages/django/core/handlers/base.py", line 108, in get_response
    response = middleware_method(request)
  File "/home/parladaddy/parlasearch/venv/local/lib/python2.7/site-packages/django/middleware/common.py", line 74, in process_request
    if (not urlresolvers.is_valid_path(request.path_info, urlconf) and
  File "/home/parladaddy/parlasearch/venv/local/lib/python2.7/site-packages/django/core/urlresolvers.py", line 646, in is_valid_path
    resolve(path, urlconf)
  File "/home/parladaddy/parlasearch/venv/local/lib/python2.7/site-packages/django/core/urlresolvers.py", line 521, in resolve
    return get_resolver(urlconf).resolve(path)
  File "/home/parladaddy/parlasearch/venv/local/lib/python2.7/site-packages/django/core/urlresolvers.py", line 365, in resolve
    for pattern in self.url_patterns:
  File "/home/parladaddy/parlasearch/venv/local/lib/python2.7/site-packages/django/core/urlresolvers.py", line 401, in url_patterns
    patterns = getattr(self.urlconf_module, "urlpatterns", self.urlconf_module)
  File "/home/parladaddy/parlasearch/venv/local/lib/python2.7/site-packages/django/core/urlresolvers.py", line 395, in urlconf_module
    self._urlconf_module = import_module(self.urlconf_name)
  File "/usr/lib/python2.7/importlib/__init__.py", line 37, in import_module
    __import__(name)
  File "/home/parladaddy/parlasearch/parlasearch/urls.py", line 18, in <module>
    from searchapi.views import query
  File "/home/parladaddy/parlasearch/searchapi/views.py", line 50
    'fq': 'speaker_i:(' + people + ') OR party_i:(' + parties ')',
                                                                ^
SyntaxError: invalid syntax
Internal Server Error: /favicon.ico
Traceback (most recent call last):
  File "/home/parladaddy/parlasearch/venv/local/lib/python2.7/site-packages/django/core/handlers/base.py", line 108, in get_response
    response = middleware_method(request)
  File "/home/parladaddy/parlasearch/venv/local/lib/python2.7/site-packages/django/middleware/common.py", line 74, in process_request
    if (not urlresolvers.is_valid_path(request.path_info, urlconf) and
  File "/home/parladaddy/parlasearch/venv/local/lib/python2.7/site-packages/django/core/urlresolvers.py", line 646, in is_valid_path
    resolve(path, urlconf)
  File "/home/parladaddy/parlasearch/venv/local/lib/python2.7/site-packages/django/core/urlresolvers.py", line 521, in resolve
    return get_resolver(urlconf).resolve(path)
  File "/home/parladaddy/parlasearch/venv/local/lib/python2.7/site-packages/django/core/urlresolvers.py", line 365, in resolve
    for pattern in self.url_patterns:
  File "/home/parladaddy/parlasearch/venv/local/lib/python2.7/site-packages/django/core/urlresolvers.py", line 401, in url_patterns
    patterns = getattr(self.urlconf_module, "urlpatterns", self.urlconf_module)
  File "/home/parladaddy/parlasearch/venv/local/lib/python2.7/site-packages/django/core/urlresolvers.py", line 395, in urlconf_module
    self._urlconf_module = import_module(self.urlconf_name)
  File "/usr/lib/python2.7/importlib/__init__.py", line 37, in import_module
    __import__(name)
  File "/home/parladaddy/parlasearch/parlasearch/urls.py", line 18, in <module>
    from searchapi.views import query
  File "/home/parladaddy/parlasearch/searchapi/views.py", line 50
    'fq': 'speaker_i:(' + people + ') OR party_i:(' + parties ')',
                                                                ^
SyntaxError: invalid syntax
Internal Server Error: /filter/kriza/11 12/5 6 7
Traceback (most recent call last):
  File "/home/parladaddy/parlasearch/venv/local/lib/python2.7/site-packages/django/core/handlers/base.py", line 108, in get_response
    response = middleware_method(request)
  File "/home/parladaddy/parlasearch/venv/local/lib/python2.7/site-packages/django/middleware/common.py", line 74, in process_request
    if (not urlresolvers.is_valid_path(request.path_info, urlconf) and
  File "/home/parladaddy/parlasearch/venv/local/lib/python2.7/site-packages/django/core/urlresolvers.py", line 646, in is_valid_path
    resolve(path, urlconf)
  File "/home/parladaddy/parlasearch/venv/local/lib/python2.7/site-packages/django/core/urlresolvers.py", line 521, in resolve
    return get_resolver(urlconf).resolve(path)
  File "/home/parladaddy/parlasearch/venv/local/lib/python2.7/site-packages/django/core/urlresolvers.py", line 365, in resolve
    for pattern in self.url_patterns:
  File "/home/parladaddy/parlasearch/venv/local/lib/python2.7/site-packages/django/core/urlresolvers.py", line 401, in url_patterns
    patterns = getattr(self.urlconf_module, "urlpatterns", self.urlconf_module)
  File "/home/parladaddy/parlasearch/venv/local/lib/python2.7/site-packages/django/core/urlresolvers.py", line 395, in urlconf_module
    self._urlconf_module = import_module(self.urlconf_name)
  File "/usr/lib/python2.7/importlib/__init__.py", line 37, in import_module
    __import__(name)
  File "/home/parladaddy/parlasearch/parlasearch/urls.py", line 18, in <module>
    from searchapi.views import query
ImportError: cannot import name query
Internal Server Error: /favicon.ico
Traceback (most recent call last):
  File "/home/parladaddy/parlasearch/venv/local/lib/python2.7/site-packages/django/core/handlers/base.py", line 108, in get_response
    response = middleware_method(request)
  File "/home/parladaddy/parlasearch/venv/local/lib/python2.7/site-packages/django/middleware/common.py", line 74, in process_request
    if (not urlresolvers.is_valid_path(request.path_info, urlconf) and
  File "/home/parladaddy/parlasearch/venv/local/lib/python2.7/site-packages/django/core/urlresolvers.py", line 646, in is_valid_path
    resolve(path, urlconf)
  File "/home/parladaddy/parlasearch/venv/local/lib/python2.7/site-packages/django/core/urlresolvers.py", line 521, in resolve
    return get_resolver(urlconf).resolve(path)
  File "/home/parladaddy/parlasearch/venv/local/lib/python2.7/site-packages/django/core/urlresolvers.py", line 365, in resolve
    for pattern in self.url_patterns:
  File "/home/parladaddy/parlasearch/venv/local/lib/python2.7/site-packages/django/core/urlresolvers.py", line 401, in url_patterns
    patterns = getattr(self.urlconf_module, "urlpatterns", self.urlconf_module)
  File "/home/parladaddy/parlasearch/venv/local/lib/python2.7/site-packages/django/core/urlresolvers.py", line 395, in urlconf_module
    self._urlconf_module = import_module(self.urlconf_name)
  File "/usr/lib/python2.7/importlib/__init__.py", line 37, in import_module
    __import__(name)
  File "/home/parladaddy/parlasearch/parlasearch/urls.py", line 18, in <module>
    from searchapi.views import query
ImportError: cannot import name query
Internal Server Error: /filter/kriza/11 12/
Traceback (most recent call last):
  File "/home/parladaddy/parlasearch/venv/local/lib/python2.7/site-packages/django/core/handlers/base.py", line 119, in get_response
    resolver_match = resolver.resolve(request.path_info)
  File "/home/parladaddy/parlasearch/venv/local/lib/python2.7/site-packages/django/core/urlresolvers.py", line 365, in resolve
    for pattern in self.url_patterns:
  File "/home/parladaddy/parlasearch/venv/local/lib/python2.7/site-packages/django/core/urlresolvers.py", line 401, in url_patterns
    patterns = getattr(self.urlconf_module, "urlpatterns", self.urlconf_module)
  File "/home/parladaddy/parlasearch/venv/local/lib/python2.7/site-packages/django/core/urlresolvers.py", line 395, in urlconf_module
    self._urlconf_module = import_module(self.urlconf_name)
  File "/usr/lib/python2.7/importlib/__init__.py", line 37, in import_module
    __import__(name)
  File "/home/parladaddy/parlasearch/parlasearch/urls.py", line 18, in <module>
    from searchapi.views import regularQuery, filterQuery
  File "/home/parladaddy/parlasearch/searchapi/views.py", line 74
    
    ^
IndentationError: expected an indented block
Internal Server Error: /favicon.ico
Traceback (most recent call last):
  File "/home/parladaddy/parlasearch/venv/local/lib/python2.7/site-packages/django/core/handlers/base.py", line 108, in get_response
    response = middleware_method(request)
  File "/home/parladaddy/parlasearch/venv/local/lib/python2.7/site-packages/django/middleware/common.py", line 74, in process_request
    if (not urlresolvers.is_valid_path(request.path_info, urlconf) and
  File "/home/parladaddy/parlasearch/venv/local/lib/python2.7/site-packages/django/core/urlresolvers.py", line 646, in is_valid_path
    resolve(path, urlconf)
  File "/home/parladaddy/parlasearch/venv/local/lib/python2.7/site-packages/django/core/urlresolvers.py", line 521, in resolve
    return get_resolver(urlconf).resolve(path)
  File "/home/parladaddy/parlasearch/venv/local/lib/python2.7/site-packages/django/core/urlresolvers.py", line 365, in resolve
    for pattern in self.url_patterns:
  File "/home/parladaddy/parlasearch/venv/local/lib/python2.7/site-packages/django/core/urlresolvers.py", line 401, in url_patterns
    patterns = getattr(self.urlconf_module, "urlpatterns", self.urlconf_module)
  File "/home/parladaddy/parlasearch/venv/local/lib/python2.7/site-packages/django/core/urlresolvers.py", line 395, in urlconf_module
    self._urlconf_module = import_module(self.urlconf_name)
  File "/usr/lib/python2.7/importlib/__init__.py", line 37, in import_module
    __import__(name)
  File "/home/parladaddy/parlasearch/parlasearch/urls.py", line 18, in <module>
    from searchapi.views import regularQuery, filterQuery
  File "/home/parladaddy/parlasearch/searchapi/views.py", line 74
    
    ^
IndentationError: expected an indented block
Not Found: /filter/posast//97
Not Found: /favicon.ico
Not Found: /filter/kriza//97
Internal Server Error: /filter/kriza
Traceback (most recent call last):
  File "/home/parladaddy/parlasearch/venv/local/lib/python2.7/site-packages/django/core/handlers/base.py", line 132, in get_response
    response = wrapped_callback(request, *callback_args, **callback_kwargs)
TypeError: filterQuery() takes at least 3 arguments (2 given)
Internal Server Error: /filter/kriza
Traceback (most recent call last):
  File "/home/parladaddy/parlasearch/venv/local/lib/python2.7/site-packages/django/core/handlers/base.py", line 132, in get_response
    response = wrapped_callback(request, *callback_args, **callback_kwargs)
  File "/home/parladaddy/parlasearch/searchapi/views.py", line 51, in filterQuery
    'fq': 'speaker_i:(' + people + ') OR party_i:(' + parties + ')',
TypeError: cannot concatenate 'str' and 'NoneType' objects
Internal Server Error: /mlt/1234
Traceback (most recent call last):
  File "/home/parladaddy/parlasearch/venv/local/lib/python2.7/site-packages/django/core/handlers/base.py", line 108, in get_response
    response = middleware_method(request)
  File "/home/parladaddy/parlasearch/venv/local/lib/python2.7/site-packages/django/middleware/common.py", line 74, in process_request
    if (not urlresolvers.is_valid_path(request.path_info, urlconf) and
  File "/home/parladaddy/parlasearch/venv/local/lib/python2.7/site-packages/django/core/urlresolvers.py", line 646, in is_valid_path
    resolve(path, urlconf)
  File "/home/parladaddy/parlasearch/venv/local/lib/python2.7/site-packages/django/core/urlresolvers.py", line 521, in resolve
    return get_resolver(urlconf).resolve(path)
  File "/home/parladaddy/parlasearch/venv/local/lib/python2.7/site-packages/django/core/urlresolvers.py", line 365, in resolve
    for pattern in self.url_patterns:
  File "/home/parladaddy/parlasearch/venv/local/lib/python2.7/site-packages/django/core/urlresolvers.py", line 401, in url_patterns
    patterns = getattr(self.urlconf_module, "urlpatterns", self.urlconf_module)
  File "/home/parladaddy/parlasearch/venv/local/lib/python2.7/site-packages/django/core/urlresolvers.py", line 395, in urlconf_module
    self._urlconf_module = import_module(self.urlconf_name)
  File "/usr/lib/python2.7/importlib/__init__.py", line 37, in import_module
    __import__(name)
  File "/home/parladaddy/parlasearch/parlasearch/urls.py", line 23, in <module>
    url(r'^mlt/(?P<speech_i>[0-9]+)', mltQuery),
NameError: name 'mltQuery' is not defined
Internal Server Error: /mlt/1234
Traceback (most recent call last):
  File "/home/parladaddy/parlasearch/venv/local/lib/python2.7/site-packages/django/core/handlers/base.py", line 108, in get_response
    response = middleware_method(request)
  File "/home/parladaddy/parlasearch/venv/local/lib/python2.7/site-packages/django/middleware/common.py", line 74, in process_request
    if (not urlresolvers.is_valid_path(request.path_info, urlconf) and
  File "/home/parladaddy/parlasearch/venv/local/lib/python2.7/site-packages/django/core/urlresolvers.py", line 646, in is_valid_path
    resolve(path, urlconf)
  File "/home/parladaddy/parlasearch/venv/local/lib/python2.7/site-packages/django/core/urlresolvers.py", line 521, in resolve
    return get_resolver(urlconf).resolve(path)
  File "/home/parladaddy/parlasearch/venv/local/lib/python2.7/site-packages/django/core/urlresolvers.py", line 365, in resolve
    for pattern in self.url_patterns:
  File "/home/parladaddy/parlasearch/venv/local/lib/python2.7/site-packages/django/core/urlresolvers.py", line 401, in url_patterns
    patterns = getattr(self.urlconf_module, "urlpatterns", self.urlconf_module)
  File "/home/parladaddy/parlasearch/venv/local/lib/python2.7/site-packages/django/core/urlresolvers.py", line 395, in urlconf_module
    self._urlconf_module = import_module(self.urlconf_name)
  File "/usr/lib/python2.7/importlib/__init__.py", line 37, in import_module
    __import__(name)
  File "/home/parladaddy/parlasearch/parlasearch/urls.py", line 23, in <module>
    url(r'^mlt/(?P<speech_i>[0-9]+)', mltQuery),
NameError: name 'mltQuery' is not defined
Internal Server Error: /mlt/1234
Traceback (most recent call last):
  File "/home/parladaddy/parlasearch/venv/local/lib/python2.7/site-packages/django/core/handlers/base.py", line 132, in get_response
    response = wrapped_callback(request, *callback_args, **callback_kwargs)
  File "/home/parladaddy/parlasearch/searchapi/views.py", line 88, in mltQuery
    r = requests.get(url)
NameError: global name 'url' is not defined
Internal Server Error: /mlt/1234
Traceback (most recent call last):
  File "/home/parladaddy/parlasearch/venv/local/lib/python2.7/site-packages/django/core/handlers/base.py", line 132, in get_response
    response = wrapped_callback(request, *callback_args, **callback_kwargs)
  File "/home/parladaddy/parlasearch/searchapi/views.py", line 88, in mltQuery
    r = requests.get(url)
NameError: global name 'url' is not defined
Internal Server Error: /mlt/1234
Traceback (most recent call last):
  File "/home/parladaddy/parlasearch/venv/local/lib/python2.7/site-packages/django/core/handlers/base.py", line 132, in get_response
    response = wrapped_callback(request, *callback_args, **callback_kwargs)
  File "/home/parladaddy/parlasearch/searchapi/views.py", line 90, in mltQuery
    return JsonResponse(r.json())
  File "/home/parladaddy/parlasearch/venv/local/lib/python2.7/site-packages/requests/models.py", line 805, in json
    return complexjson.loads(self.text, **kwargs)
  File "/usr/lib/python2.7/json/__init__.py", line 338, in loads
    return _default_decoder.decode(s)
  File "/usr/lib/python2.7/json/decoder.py", line 366, in decode
    obj, end = self.raw_decode(s, idx=_w(s, 0).end())
  File "/usr/lib/python2.7/json/decoder.py", line 384, in raw_decode
    raise ValueError("No JSON object could be decoded")
ValueError: No JSON object could be decoded
Not Found: /favicon.ico
