Internal Server Error: /osamosvojitev
Traceback (most recent call last):
  File "/home/parladaddy/parlasearch/venv/local/lib/python2.7/site-packages/django/core/handlers/base.py", line 108, in get_response
    response = middleware_method(request)
  File "/home/parladaddy/parlasearch/venv/local/lib/python2.7/site-packages/django/middleware/common.py", line 74, in process_request
    if (not urlresolvers.is_valid_path(request.path_info, urlconf) and
  File "/home/parladaddy/parlasearch/venv/local/lib/python2.7/site-packages/django/core/urlresolvers.py", line 646, in is_valid_path
    resolve(path, urlconf)
  File "/home/parladaddy/parlasearch/venv/local/lib/python2.7/site-packages/django/core/urlresolvers.py", line 521, in resolve
    return get_resolver(urlconf).resolve(path)
  File "/home/parladaddy/parlasearch/venv/local/lib/python2.7/site-packages/django/core/urlresolvers.py", line 365, in resolve
    for pattern in self.url_patterns:
  File "/home/parladaddy/parlasearch/venv/local/lib/python2.7/site-packages/django/core/urlresolvers.py", line 401, in url_patterns
    patterns = getattr(self.urlconf_module, "urlpatterns", self.urlconf_module)
  File "/home/parladaddy/parlasearch/venv/local/lib/python2.7/site-packages/django/core/urlresolvers.py", line 395, in urlconf_module
    self._urlconf_module = import_module(self.urlconf_name)
  File "/usr/lib/python2.7/importlib/__init__.py", line 37, in import_module
    __import__(name)
  File "/home/parladaddy/parlasearch/parlasearch/urls.py", line 21, in <module>
    url(r'^?P<person_id>[a-z A-Z 0-9 \ -]+', parlasearch.views.query),
NameError: name 'parlasearch' is not defined
Internal Server Error: /osamosvojitev
Traceback (most recent call last):
  File "/home/parladaddy/parlasearch/venv/local/lib/python2.7/site-packages/django/core/handlers/base.py", line 108, in get_response
    response = middleware_method(request)
  File "/home/parladaddy/parlasearch/venv/local/lib/python2.7/site-packages/django/middleware/common.py", line 74, in process_request
    if (not urlresolvers.is_valid_path(request.path_info, urlconf) and
  File "/home/parladaddy/parlasearch/venv/local/lib/python2.7/site-packages/django/core/urlresolvers.py", line 646, in is_valid_path
    resolve(path, urlconf)
  File "/home/parladaddy/parlasearch/venv/local/lib/python2.7/site-packages/django/core/urlresolvers.py", line 521, in resolve
    return get_resolver(urlconf).resolve(path)
  File "/home/parladaddy/parlasearch/venv/local/lib/python2.7/site-packages/django/core/urlresolvers.py", line 365, in resolve
    for pattern in self.url_patterns:
  File "/home/parladaddy/parlasearch/venv/local/lib/python2.7/site-packages/django/core/urlresolvers.py", line 401, in url_patterns
    patterns = getattr(self.urlconf_module, "urlpatterns", self.urlconf_module)
  File "/home/parladaddy/parlasearch/venv/local/lib/python2.7/site-packages/django/core/urlresolvers.py", line 395, in urlconf_module
    self._urlconf_module = import_module(self.urlconf_name)
  File "/usr/lib/python2.7/importlib/__init__.py", line 37, in import_module
    __import__(name)
  File "/home/parladaddy/parlasearch/parlasearch/urls.py", line 21, in <module>
    url(r'^?P<person_id>[a-z A-Z 0-9 \ -]+', searchapi.views.query),
NameError: name 'searchapi' is not defined
Internal Server Error: /osamosvojitev
Traceback (most recent call last):
  File "/home/parladaddy/parlasearch/venv/local/lib/python2.7/site-packages/django/core/handlers/base.py", line 108, in get_response
    response = middleware_method(request)
  File "/home/parladaddy/parlasearch/venv/local/lib/python2.7/site-packages/django/middleware/common.py", line 74, in process_request
    if (not urlresolvers.is_valid_path(request.path_info, urlconf) and
  File "/home/parladaddy/parlasearch/venv/local/lib/python2.7/site-packages/django/core/urlresolvers.py", line 646, in is_valid_path
    resolve(path, urlconf)
  File "/home/parladaddy/parlasearch/venv/local/lib/python2.7/site-packages/django/core/urlresolvers.py", line 521, in resolve
    return get_resolver(urlconf).resolve(path)
  File "/home/parladaddy/parlasearch/venv/local/lib/python2.7/site-packages/django/core/urlresolvers.py", line 365, in resolve
    for pattern in self.url_patterns:
  File "/home/parladaddy/parlasearch/venv/local/lib/python2.7/site-packages/django/core/urlresolvers.py", line 401, in url_patterns
    patterns = getattr(self.urlconf_module, "urlpatterns", self.urlconf_module)
  File "/home/parladaddy/parlasearch/venv/local/lib/python2.7/site-packages/django/core/urlresolvers.py", line 395, in urlconf_module
    self._urlconf_module = import_module(self.urlconf_name)
  File "/usr/lib/python2.7/importlib/__init__.py", line 37, in import_module
    __import__(name)
  File "/home/parladaddy/parlasearch/parlasearch/urls.py", line 21, in <module>
    url(r'^?P<person_id>[a-z A-Z 0-9 \ -]+', searchapi.views.query),
NameError: name 'searchapi' is not defined
Internal Server Error: /osamosvojitev
Traceback (most recent call last):
  File "/home/parladaddy/parlasearch/venv/local/lib/python2.7/site-packages/django/core/handlers/base.py", line 108, in get_response
    response = middleware_method(request)
  File "/home/parladaddy/parlasearch/venv/local/lib/python2.7/site-packages/django/middleware/common.py", line 74, in process_request
    if (not urlresolvers.is_valid_path(request.path_info, urlconf) and
  File "/home/parladaddy/parlasearch/venv/local/lib/python2.7/site-packages/django/core/urlresolvers.py", line 646, in is_valid_path
    resolve(path, urlconf)
  File "/home/parladaddy/parlasearch/venv/local/lib/python2.7/site-packages/django/core/urlresolvers.py", line 521, in resolve
    return get_resolver(urlconf).resolve(path)
  File "/home/parladaddy/parlasearch/venv/local/lib/python2.7/site-packages/django/core/urlresolvers.py", line 367, in resolve
    sub_match = pattern.resolve(new_path)
  File "/home/parladaddy/parlasearch/venv/local/lib/python2.7/site-packages/django/core/urlresolvers.py", line 226, in resolve
    match = self.regex.search(path)
  File "/home/parladaddy/parlasearch/venv/local/lib/python2.7/site-packages/django/core/urlresolvers.py", line 194, in regex
    (regex, six.text_type(e)))
ImproperlyConfigured: "^?P<person_id>[a-z A-Z 0-9 \ -]+" is not a valid regular expression: nothing to repeat
Internal Server Error: /osamosvojitev
Traceback (most recent call last):
  File "/home/parladaddy/parlasearch/venv/local/lib/python2.7/site-packages/django/core/handlers/base.py", line 108, in get_response
    response = middleware_method(request)
  File "/home/parladaddy/parlasearch/venv/local/lib/python2.7/site-packages/django/middleware/common.py", line 74, in process_request
    if (not urlresolvers.is_valid_path(request.path_info, urlconf) and
  File "/home/parladaddy/parlasearch/venv/local/lib/python2.7/site-packages/django/core/urlresolvers.py", line 646, in is_valid_path
    resolve(path, urlconf)
  File "/home/parladaddy/parlasearch/venv/local/lib/python2.7/site-packages/django/core/urlresolvers.py", line 521, in resolve
    return get_resolver(urlconf).resolve(path)
  File "/home/parladaddy/parlasearch/venv/local/lib/python2.7/site-packages/django/core/urlresolvers.py", line 367, in resolve
    sub_match = pattern.resolve(new_path)
  File "/home/parladaddy/parlasearch/venv/local/lib/python2.7/site-packages/django/core/urlresolvers.py", line 226, in resolve
    match = self.regex.search(path)
  File "/home/parladaddy/parlasearch/venv/local/lib/python2.7/site-packages/django/core/urlresolvers.py", line 194, in regex
    (regex, six.text_type(e)))
ImproperlyConfigured: "^?P<person_id>([a-z A-Z 0-9 \ -])+" is not a valid regular expression: nothing to repeat
Internal Server Error: /osamosvojitev
Traceback (most recent call last):
  File "/home/parladaddy/parlasearch/venv/local/lib/python2.7/site-packages/django/core/handlers/base.py", line 108, in get_response
    response = middleware_method(request)
  File "/home/parladaddy/parlasearch/venv/local/lib/python2.7/site-packages/django/middleware/common.py", line 74, in process_request
    if (not urlresolvers.is_valid_path(request.path_info, urlconf) and
  File "/home/parladaddy/parlasearch/venv/local/lib/python2.7/site-packages/django/core/urlresolvers.py", line 646, in is_valid_path
    resolve(path, urlconf)
  File "/home/parladaddy/parlasearch/venv/local/lib/python2.7/site-packages/django/core/urlresolvers.py", line 521, in resolve
    return get_resolver(urlconf).resolve(path)
  File "/home/parladaddy/parlasearch/venv/local/lib/python2.7/site-packages/django/core/urlresolvers.py", line 367, in resolve
    sub_match = pattern.resolve(new_path)
  File "/home/parladaddy/parlasearch/venv/local/lib/python2.7/site-packages/django/core/urlresolvers.py", line 226, in resolve
    match = self.regex.search(path)
  File "/home/parladaddy/parlasearch/venv/local/lib/python2.7/site-packages/django/core/urlresolvers.py", line 194, in regex
    (regex, six.text_type(e)))
ImproperlyConfigured: "^?P<person_id>([a-z A-Z 0-9 \ -])+" is not a valid regular expression: nothing to repeat
Internal Server Error: /osamosvojitev
Traceback (most recent call last):
  File "/home/parladaddy/parlasearch/venv/local/lib/python2.7/site-packages/django/core/handlers/base.py", line 108, in get_response
    response = middleware_method(request)
  File "/home/parladaddy/parlasearch/venv/local/lib/python2.7/site-packages/django/middleware/common.py", line 74, in process_request
    if (not urlresolvers.is_valid_path(request.path_info, urlconf) and
  File "/home/parladaddy/parlasearch/venv/local/lib/python2.7/site-packages/django/core/urlresolvers.py", line 646, in is_valid_path
    resolve(path, urlconf)
  File "/home/parladaddy/parlasearch/venv/local/lib/python2.7/site-packages/django/core/urlresolvers.py", line 521, in resolve
    return get_resolver(urlconf).resolve(path)
  File "/home/parladaddy/parlasearch/venv/local/lib/python2.7/site-packages/django/core/urlresolvers.py", line 367, in resolve
    sub_match = pattern.resolve(new_path)
  File "/home/parladaddy/parlasearch/venv/local/lib/python2.7/site-packages/django/core/urlresolvers.py", line 226, in resolve
    match = self.regex.search(path)
  File "/home/parladaddy/parlasearch/venv/local/lib/python2.7/site-packages/django/core/urlresolvers.py", line 194, in regex
    (regex, six.text_type(e)))
ImproperlyConfigured: "^?P<person_id>([a-z A-Z 0-9 \ -]+)" is not a valid regular expression: nothing to repeat
Internal Server Error: /osamosvojitev
Traceback (most recent call last):
  File "/home/parladaddy/parlasearch/venv/local/lib/python2.7/site-packages/django/core/handlers/base.py", line 108, in get_response
    response = middleware_method(request)
  File "/home/parladaddy/parlasearch/venv/local/lib/python2.7/site-packages/django/middleware/common.py", line 74, in process_request
    if (not urlresolvers.is_valid_path(request.path_info, urlconf) and
  File "/home/parladaddy/parlasearch/venv/local/lib/python2.7/site-packages/django/core/urlresolvers.py", line 646, in is_valid_path
    resolve(path, urlconf)
  File "/home/parladaddy/parlasearch/venv/local/lib/python2.7/site-packages/django/core/urlresolvers.py", line 521, in resolve
    return get_resolver(urlconf).resolve(path)
  File "/home/parladaddy/parlasearch/venv/local/lib/python2.7/site-packages/django/core/urlresolvers.py", line 367, in resolve
    sub_match = pattern.resolve(new_path)
  File "/home/parladaddy/parlasearch/venv/local/lib/python2.7/site-packages/django/core/urlresolvers.py", line 226, in resolve
    match = self.regex.search(path)
  File "/home/parladaddy/parlasearch/venv/local/lib/python2.7/site-packages/django/core/urlresolvers.py", line 194, in regex
    (regex, six.text_type(e)))
ImproperlyConfigured: "^?P<person_id>([a-z A-Z 0-9 -]+)" is not a valid regular expression: nothing to repeat
Internal Server Error: /osamosvojitev
Traceback (most recent call last):
  File "/home/parladaddy/parlasearch/venv/local/lib/python2.7/site-packages/django/core/handlers/base.py", line 108, in get_response
    response = middleware_method(request)
  File "/home/parladaddy/parlasearch/venv/local/lib/python2.7/site-packages/django/middleware/common.py", line 74, in process_request
    if (not urlresolvers.is_valid_path(request.path_info, urlconf) and
  File "/home/parladaddy/parlasearch/venv/local/lib/python2.7/site-packages/django/core/urlresolvers.py", line 646, in is_valid_path
    resolve(path, urlconf)
  File "/home/parladaddy/parlasearch/venv/local/lib/python2.7/site-packages/django/core/urlresolvers.py", line 521, in resolve
    return get_resolver(urlconf).resolve(path)
  File "/home/parladaddy/parlasearch/venv/local/lib/python2.7/site-packages/django/core/urlresolvers.py", line 367, in resolve
    sub_match = pattern.resolve(new_path)
  File "/home/parladaddy/parlasearch/venv/local/lib/python2.7/site-packages/django/core/urlresolvers.py", line 226, in resolve
    match = self.regex.search(path)
  File "/home/parladaddy/parlasearch/venv/local/lib/python2.7/site-packages/django/core/urlresolvers.py", line 194, in regex
    (regex, six.text_type(e)))
ImproperlyConfigured: "^?P<person_id>([a-z A-Z 0-9 -]+)" is not a valid regular expression: nothing to repeat
Internal Server Error: /osamosvojitev
Traceback (most recent call last):
  File "/home/parladaddy/parlasearch/venv/local/lib/python2.7/site-packages/django/core/handlers/base.py", line 108, in get_response
    response = middleware_method(request)
  File "/home/parladaddy/parlasearch/venv/local/lib/python2.7/site-packages/django/middleware/common.py", line 74, in process_request
    if (not urlresolvers.is_valid_path(request.path_info, urlconf) and
  File "/home/parladaddy/parlasearch/venv/local/lib/python2.7/site-packages/django/core/urlresolvers.py", line 646, in is_valid_path
    resolve(path, urlconf)
  File "/home/parladaddy/parlasearch/venv/local/lib/python2.7/site-packages/django/core/urlresolvers.py", line 521, in resolve
    return get_resolver(urlconf).resolve(path)
  File "/home/parladaddy/parlasearch/venv/local/lib/python2.7/site-packages/django/core/urlresolvers.py", line 367, in resolve
    sub_match = pattern.resolve(new_path)
  File "/home/parladaddy/parlasearch/venv/local/lib/python2.7/site-packages/django/core/urlresolvers.py", line 226, in resolve
    match = self.regex.search(path)
  File "/home/parladaddy/parlasearch/venv/local/lib/python2.7/site-packages/django/core/urlresolvers.py", line 194, in regex
    (regex, six.text_type(e)))
ImproperlyConfigured: "^?P<person_id>([a-zA-Z0-9- ]+)" is not a valid regular expression: nothing to repeat
Internal Server Error: /osamosvojitev
Traceback (most recent call last):
  File "/home/parladaddy/parlasearch/venv/local/lib/python2.7/site-packages/django/core/handlers/base.py", line 108, in get_response
    response = middleware_method(request)
  File "/home/parladaddy/parlasearch/venv/local/lib/python2.7/site-packages/django/middleware/common.py", line 74, in process_request
    if (not urlresolvers.is_valid_path(request.path_info, urlconf) and
  File "/home/parladaddy/parlasearch/venv/local/lib/python2.7/site-packages/django/core/urlresolvers.py", line 646, in is_valid_path
    resolve(path, urlconf)
  File "/home/parladaddy/parlasearch/venv/local/lib/python2.7/site-packages/django/core/urlresolvers.py", line 521, in resolve
    return get_resolver(urlconf).resolve(path)
  File "/home/parladaddy/parlasearch/venv/local/lib/python2.7/site-packages/django/core/urlresolvers.py", line 367, in resolve
    sub_match = pattern.resolve(new_path)
  File "/home/parladaddy/parlasearch/venv/local/lib/python2.7/site-packages/django/core/urlresolvers.py", line 226, in resolve
    match = self.regex.search(path)
  File "/home/parladaddy/parlasearch/venv/local/lib/python2.7/site-packages/django/core/urlresolvers.py", line 194, in regex
    (regex, six.text_type(e)))
ImproperlyConfigured: "^?P<person_id>([a-zA-Z0-9\-]+)" is not a valid regular expression: nothing to repeat
Internal Server Error: /osamosvojitev
Traceback (most recent call last):
  File "/home/parladaddy/parlasearch/venv/local/lib/python2.7/site-packages/django/core/handlers/base.py", line 108, in get_response
    response = middleware_method(request)
  File "/home/parladaddy/parlasearch/venv/local/lib/python2.7/site-packages/django/middleware/common.py", line 74, in process_request
    if (not urlresolvers.is_valid_path(request.path_info, urlconf) and
  File "/home/parladaddy/parlasearch/venv/local/lib/python2.7/site-packages/django/core/urlresolvers.py", line 646, in is_valid_path
    resolve(path, urlconf)
  File "/home/parladaddy/parlasearch/venv/local/lib/python2.7/site-packages/django/core/urlresolvers.py", line 521, in resolve
    return get_resolver(urlconf).resolve(path)
  File "/home/parladaddy/parlasearch/venv/local/lib/python2.7/site-packages/django/core/urlresolvers.py", line 367, in resolve
    sub_match = pattern.resolve(new_path)
  File "/home/parladaddy/parlasearch/venv/local/lib/python2.7/site-packages/django/core/urlresolvers.py", line 226, in resolve
    match = self.regex.search(path)
  File "/home/parladaddy/parlasearch/venv/local/lib/python2.7/site-packages/django/core/urlresolvers.py", line 194, in regex
    (regex, six.text_type(e)))
ImproperlyConfigured: "^?P<person_id>([a-zA-Z0-9]+)" is not a valid regular expression: nothing to repeat
Internal Server Error: /osamosvojitev
Traceback (most recent call last):
  File "/home/parladaddy/parlasearch/venv/local/lib/python2.7/site-packages/django/core/handlers/base.py", line 108, in get_response
    response = middleware_method(request)
  File "/home/parladaddy/parlasearch/venv/local/lib/python2.7/site-packages/django/middleware/common.py", line 74, in process_request
    if (not urlresolvers.is_valid_path(request.path_info, urlconf) and
  File "/home/parladaddy/parlasearch/venv/local/lib/python2.7/site-packages/django/core/urlresolvers.py", line 646, in is_valid_path
    resolve(path, urlconf)
  File "/home/parladaddy/parlasearch/venv/local/lib/python2.7/site-packages/django/core/urlresolvers.py", line 521, in resolve
    return get_resolver(urlconf).resolve(path)
  File "/home/parladaddy/parlasearch/venv/local/lib/python2.7/site-packages/django/core/urlresolvers.py", line 367, in resolve
    sub_match = pattern.resolve(new_path)
  File "/home/parladaddy/parlasearch/venv/local/lib/python2.7/site-packages/django/core/urlresolvers.py", line 226, in resolve
    match = self.regex.search(path)
  File "/home/parladaddy/parlasearch/venv/local/lib/python2.7/site-packages/django/core/urlresolvers.py", line 194, in regex
    (regex, six.text_type(e)))
ImproperlyConfigured: "^?P<person_id>(\w+)" is not a valid regular expression: nothing to repeat
Internal Server Error: /osamosvojitev
Traceback (most recent call last):
  File "/home/parladaddy/parlasearch/venv/local/lib/python2.7/site-packages/django/core/handlers/base.py", line 108, in get_response
    response = middleware_method(request)
  File "/home/parladaddy/parlasearch/venv/local/lib/python2.7/site-packages/django/middleware/common.py", line 74, in process_request
    if (not urlresolvers.is_valid_path(request.path_info, urlconf) and
  File "/home/parladaddy/parlasearch/venv/local/lib/python2.7/site-packages/django/core/urlresolvers.py", line 646, in is_valid_path
    resolve(path, urlconf)
  File "/home/parladaddy/parlasearch/venv/local/lib/python2.7/site-packages/django/core/urlresolvers.py", line 521, in resolve
    return get_resolver(urlconf).resolve(path)
  File "/home/parladaddy/parlasearch/venv/local/lib/python2.7/site-packages/django/core/urlresolvers.py", line 367, in resolve
    sub_match = pattern.resolve(new_path)
  File "/home/parladaddy/parlasearch/venv/local/lib/python2.7/site-packages/django/core/urlresolvers.py", line 226, in resolve
    match = self.regex.search(path)
  File "/home/parladaddy/parlasearch/venv/local/lib/python2.7/site-packages/django/core/urlresolvers.py", line 194, in regex
    (regex, six.text_type(e)))
ImproperlyConfigured: "^?P<person_id>\w+" is not a valid regular expression: nothing to repeat
Not Found: /osamosvojitev
Internal Server Error: /osamosvojitev
Traceback (most recent call last):
  File "/home/parladaddy/parlasearch/venv/local/lib/python2.7/site-packages/django/core/handlers/base.py", line 132, in get_response
    response = wrapped_callback(request, *callback_args, **callback_kwargs)
TypeError: query() got an unexpected keyword argument 'person_id'
Not Found: /
Internal Server Error: /osamosvojitev
Traceback (most recent call last):
  File "/home/parladaddy/parlasearch/venv/local/lib/python2.7/site-packages/django/core/handlers/base.py", line 108, in get_response
    response = middleware_method(request)
  File "/home/parladaddy/parlasearch/venv/local/lib/python2.7/site-packages/django/middleware/common.py", line 74, in process_request
    if (not urlresolvers.is_valid_path(request.path_info, urlconf) and
  File "/home/parladaddy/parlasearch/venv/local/lib/python2.7/site-packages/django/core/urlresolvers.py", line 646, in is_valid_path
    resolve(path, urlconf)
  File "/home/parladaddy/parlasearch/venv/local/lib/python2.7/site-packages/django/core/urlresolvers.py", line 521, in resolve
    return get_resolver(urlconf).resolve(path)
  File "/home/parladaddy/parlasearch/venv/local/lib/python2.7/site-packages/django/core/urlresolvers.py", line 365, in resolve
    for pattern in self.url_patterns:
  File "/home/parladaddy/parlasearch/venv/local/lib/python2.7/site-packages/django/core/urlresolvers.py", line 401, in url_patterns
    patterns = getattr(self.urlconf_module, "urlpatterns", self.urlconf_module)
  File "/home/parladaddy/parlasearch/venv/local/lib/python2.7/site-packages/django/core/urlresolvers.py", line 395, in urlconf_module
    self._urlconf_module = import_module(self.urlconf_name)
  File "/usr/lib/python2.7/importlib/__init__.py", line 37, in import_module
    __import__(name)
  File "/home/parladaddy/parlasearch/parlasearch/urls.py", line 18, in <module>
    from searchapi.views import query
  File "/home/parladaddy/parlasearch/searchapi/views.py", line 9
    'q': 'content_t',
      ^
SyntaxError: invalid syntax
Internal Server Error: /favicon.ico
Traceback (most recent call last):
  File "/home/parladaddy/parlasearch/venv/local/lib/python2.7/site-packages/django/core/handlers/base.py", line 108, in get_response
    response = middleware_method(request)
  File "/home/parladaddy/parlasearch/venv/local/lib/python2.7/site-packages/django/middleware/common.py", line 74, in process_request
    if (not urlresolvers.is_valid_path(request.path_info, urlconf) and
  File "/home/parladaddy/parlasearch/venv/local/lib/python2.7/site-packages/django/core/urlresolvers.py", line 646, in is_valid_path
    resolve(path, urlconf)
  File "/home/parladaddy/parlasearch/venv/local/lib/python2.7/site-packages/django/core/urlresolvers.py", line 521, in resolve
    return get_resolver(urlconf).resolve(path)
  File "/home/parladaddy/parlasearch/venv/local/lib/python2.7/site-packages/django/core/urlresolvers.py", line 365, in resolve
    for pattern in self.url_patterns:
  File "/home/parladaddy/parlasearch/venv/local/lib/python2.7/site-packages/django/core/urlresolvers.py", line 401, in url_patterns
    patterns = getattr(self.urlconf_module, "urlpatterns", self.urlconf_module)
  File "/home/parladaddy/parlasearch/venv/local/lib/python2.7/site-packages/django/core/urlresolvers.py", line 395, in urlconf_module
    self._urlconf_module = import_module(self.urlconf_name)
  File "/usr/lib/python2.7/importlib/__init__.py", line 37, in import_module
    __import__(name)
  File "/home/parladaddy/parlasearch/parlasearch/urls.py", line 18, in <module>
    from searchapi.views import query
  File "/home/parladaddy/parlasearch/searchapi/views.py", line 9
    'q': 'content_t',
      ^
SyntaxError: invalid syntax
Internal Server Error: /osamosvojitev
Traceback (most recent call last):
  File "/home/parladaddy/parlasearch/venv/local/lib/python2.7/site-packages/django/core/handlers/base.py", line 108, in get_response
    response = middleware_method(request)
  File "/home/parladaddy/parlasearch/venv/local/lib/python2.7/site-packages/django/middleware/common.py", line 74, in process_request
    if (not urlresolvers.is_valid_path(request.path_info, urlconf) and
  File "/home/parladaddy/parlasearch/venv/local/lib/python2.7/site-packages/django/core/urlresolvers.py", line 646, in is_valid_path
    resolve(path, urlconf)
  File "/home/parladaddy/parlasearch/venv/local/lib/python2.7/site-packages/django/core/urlresolvers.py", line 521, in resolve
    return get_resolver(urlconf).resolve(path)
  File "/home/parladaddy/parlasearch/venv/local/lib/python2.7/site-packages/django/core/urlresolvers.py", line 365, in resolve
    for pattern in self.url_patterns:
  File "/home/parladaddy/parlasearch/venv/local/lib/python2.7/site-packages/django/core/urlresolvers.py", line 401, in url_patterns
    patterns = getattr(self.urlconf_module, "urlpatterns", self.urlconf_module)
  File "/home/parladaddy/parlasearch/venv/local/lib/python2.7/site-packages/django/core/urlresolvers.py", line 395, in urlconf_module
    self._urlconf_module = import_module(self.urlconf_name)
  File "/usr/lib/python2.7/importlib/__init__.py", line 37, in import_module
    __import__(name)
  File "/home/parladaddy/parlasearch/parlasearch/urls.py", line 18, in <module>
    from searchapi.views import query
  File "/home/parladaddy/parlasearch/searchapi/views.py", line 9
    'q': 'content_t',
      ^
SyntaxError: invalid syntax
Internal Server Error: /favicon.ico
Traceback (most recent call last):
  File "/home/parladaddy/parlasearch/venv/local/lib/python2.7/site-packages/django/core/handlers/base.py", line 108, in get_response
    response = middleware_method(request)
  File "/home/parladaddy/parlasearch/venv/local/lib/python2.7/site-packages/django/middleware/common.py", line 74, in process_request
    if (not urlresolvers.is_valid_path(request.path_info, urlconf) and
  File "/home/parladaddy/parlasearch/venv/local/lib/python2.7/site-packages/django/core/urlresolvers.py", line 646, in is_valid_path
    resolve(path, urlconf)
  File "/home/parladaddy/parlasearch/venv/local/lib/python2.7/site-packages/django/core/urlresolvers.py", line 521, in resolve
    return get_resolver(urlconf).resolve(path)
  File "/home/parladaddy/parlasearch/venv/local/lib/python2.7/site-packages/django/core/urlresolvers.py", line 365, in resolve
    for pattern in self.url_patterns:
  File "/home/parladaddy/parlasearch/venv/local/lib/python2.7/site-packages/django/core/urlresolvers.py", line 401, in url_patterns
    patterns = getattr(self.urlconf_module, "urlpatterns", self.urlconf_module)
  File "/home/parladaddy/parlasearch/venv/local/lib/python2.7/site-packages/django/core/urlresolvers.py", line 395, in urlconf_module
    self._urlconf_module = import_module(self.urlconf_name)
  File "/usr/lib/python2.7/importlib/__init__.py", line 37, in import_module
    __import__(name)
  File "/home/parladaddy/parlasearch/parlasearch/urls.py", line 18, in <module>
    from searchapi.views import query
  File "/home/parladaddy/parlasearch/searchapi/views.py", line 9
    'q': 'content_t',
      ^
SyntaxError: invalid syntax
Internal Server Error: /osamosvojitev
Traceback (most recent call last):
  File "/home/parladaddy/parlasearch/venv/local/lib/python2.7/site-packages/django/core/handlers/base.py", line 108, in get_response
    response = middleware_method(request)
  File "/home/parladaddy/parlasearch/venv/local/lib/python2.7/site-packages/django/middleware/common.py", line 74, in process_request
    if (not urlresolvers.is_valid_path(request.path_info, urlconf) and
  File "/home/parladaddy/parlasearch/venv/local/lib/python2.7/site-packages/django/core/urlresolvers.py", line 646, in is_valid_path
    resolve(path, urlconf)
  File "/home/parladaddy/parlasearch/venv/local/lib/python2.7/site-packages/django/core/urlresolvers.py", line 521, in resolve
    return get_resolver(urlconf).resolve(path)
  File "/home/parladaddy/parlasearch/venv/local/lib/python2.7/site-packages/django/core/urlresolvers.py", line 365, in resolve
    for pattern in self.url_patterns:
  File "/home/parladaddy/parlasearch/venv/local/lib/python2.7/site-packages/django/core/urlresolvers.py", line 401, in url_patterns
    patterns = getattr(self.urlconf_module, "urlpatterns", self.urlconf_module)
  File "/home/parladaddy/parlasearch/venv/local/lib/python2.7/site-packages/django/core/urlresolvers.py", line 395, in urlconf_module
    self._urlconf_module = import_module(self.urlconf_name)
  File "/usr/lib/python2.7/importlib/__init__.py", line 37, in import_module
    __import__(name)
  File "/home/parladaddy/parlasearch/parlasearch/urls.py", line 18, in <module>
    from searchapi.views import query
  File "/home/parladaddy/parlasearch/searchapi/views.py", line 9
    'q': 'content_t',
      ^
SyntaxError: invalid syntax
Internal Server Error: /favicon.ico
Traceback (most recent call last):
  File "/home/parladaddy/parlasearch/venv/local/lib/python2.7/site-packages/django/core/handlers/base.py", line 108, in get_response
    response = middleware_method(request)
  File "/home/parladaddy/parlasearch/venv/local/lib/python2.7/site-packages/django/middleware/common.py", line 74, in process_request
    if (not urlresolvers.is_valid_path(request.path_info, urlconf) and
  File "/home/parladaddy/parlasearch/venv/local/lib/python2.7/site-packages/django/core/urlresolvers.py", line 646, in is_valid_path
    resolve(path, urlconf)
  File "/home/parladaddy/parlasearch/venv/local/lib/python2.7/site-packages/django/core/urlresolvers.py", line 521, in resolve
    return get_resolver(urlconf).resolve(path)
  File "/home/parladaddy/parlasearch/venv/local/lib/python2.7/site-packages/django/core/urlresolvers.py", line 365, in resolve
    for pattern in self.url_patterns:
  File "/home/parladaddy/parlasearch/venv/local/lib/python2.7/site-packages/django/core/urlresolvers.py", line 401, in url_patterns
    patterns = getattr(self.urlconf_module, "urlpatterns", self.urlconf_module)
  File "/home/parladaddy/parlasearch/venv/local/lib/python2.7/site-packages/django/core/urlresolvers.py", line 395, in urlconf_module
    self._urlconf_module = import_module(self.urlconf_name)
  File "/usr/lib/python2.7/importlib/__init__.py", line 37, in import_module
    __import__(name)
  File "/home/parladaddy/parlasearch/parlasearch/urls.py", line 18, in <module>
    from searchapi.views import query
  File "/home/parladaddy/parlasearch/searchapi/views.py", line 9
    'q': 'content_t',
      ^
SyntaxError: invalid syntax
Internal Server Error: /osamosvojitev
Traceback (most recent call last):
  File "/home/parladaddy/parlasearch/venv/local/lib/python2.7/site-packages/django/core/handlers/base.py", line 132, in get_response
    response = wrapped_callback(request, *callback_args, **callback_kwargs)
  File "/home/parladaddy/parlasearch/searchapi/views.py", line 28, in query
    url = solr_url
UnboundLocalError: local variable 'solr_url' referenced before assignment
Internal Server Error: /favicon.ico
Traceback (most recent call last):
  File "/home/parladaddy/parlasearch/venv/local/lib/python2.7/site-packages/django/core/handlers/base.py", line 132, in get_response
    response = wrapped_callback(request, *callback_args, **callback_kwargs)
  File "/home/parladaddy/parlasearch/searchapi/views.py", line 28, in query
    url = solr_url
UnboundLocalError: local variable 'solr_url' referenced before assignment
Not Found: /"osamosvojitev je bila"
Not Found: /
Not Found: /
Internal Server Error: /filter/kriza/11 12/5 6 7/
Traceback (most recent call last):
  File "/home/parladaddy/parlasearch/venv/local/lib/python2.7/site-packages/django/core/handlers/base.py", line 119, in get_response
    resolver_match = resolver.resolve(request.path_info)
  File "/home/parladaddy/parlasearch/venv/local/lib/python2.7/site-packages/django/core/urlresolvers.py", line 365, in resolve
    for pattern in self.url_patterns:
  File "/home/parladaddy/parlasearch/venv/local/lib/python2.7/site-packages/django/core/urlresolvers.py", line 401, in url_patterns
    patterns = getattr(self.urlconf_module, "urlpatterns", self.urlconf_module)
  File "/home/parladaddy/parlasearch/venv/local/lib/python2.7/site-packages/django/core/urlresolvers.py", line 395, in urlconf_module
    self._urlconf_module = import_module(self.urlconf_name)
  File "/usr/lib/python2.7/importlib/__init__.py", line 37, in import_module
    __import__(name)
  File "/home/parladaddy/parlasearch/parlasearch/urls.py", line 18, in <module>
    from searchapi.views import query
  File "/home/parladaddy/parlasearch/searchapi/views.py", line 50
    'fq': 'speaker_i:(' + people + ') OR party_i:(' + parties ')',
                                                                ^
SyntaxError: invalid syntax
Internal Server Error: /favicon.ico
Traceback (most recent call last):
  File "/home/parladaddy/parlasearch/venv/local/lib/python2.7/site-packages/django/core/handlers/base.py", line 108, in get_response
    response = middleware_method(request)
  File "/home/parladaddy/parlasearch/venv/local/lib/python2.7/site-packages/django/middleware/common.py", line 74, in process_request
    if (not urlresolvers.is_valid_path(request.path_info, urlconf) and
  File "/home/parladaddy/parlasearch/venv/local/lib/python2.7/site-packages/django/core/urlresolvers.py", line 646, in is_valid_path
    resolve(path, urlconf)
  File "/home/parladaddy/parlasearch/venv/local/lib/python2.7/site-packages/django/core/urlresolvers.py", line 521, in resolve
    return get_resolver(urlconf).resolve(path)
  File "/home/parladaddy/parlasearch/venv/local/lib/python2.7/site-packages/django/core/urlresolvers.py", line 365, in resolve
    for pattern in self.url_patterns:
  File "/home/parladaddy/parlasearch/venv/local/lib/python2.7/site-packages/django/core/urlresolvers.py", line 401, in url_patterns
    patterns = getattr(self.urlconf_module, "urlpatterns", self.urlconf_module)
  File "/home/parladaddy/parlasearch/venv/local/lib/python2.7/site-packages/django/core/urlresolvers.py", line 395, in urlconf_module
    self._urlconf_module = import_module(self.urlconf_name)
  File "/usr/lib/python2.7/importlib/__init__.py", line 37, in import_module
    __import__(name)
  File "/home/parladaddy/parlasearch/parlasearch/urls.py", line 18, in <module>
    from searchapi.views import query
  File "/home/parladaddy/parlasearch/searchapi/views.py", line 50
    'fq': 'speaker_i:(' + people + ') OR party_i:(' + parties ')',
                                                                ^
SyntaxError: invalid syntax
Internal Server Error: /filter/kriza/11 12/5 6 7
Traceback (most recent call last):
  File "/home/parladaddy/parlasearch/venv/local/lib/python2.7/site-packages/django/core/handlers/base.py", line 108, in get_response
    response = middleware_method(request)
  File "/home/parladaddy/parlasearch/venv/local/lib/python2.7/site-packages/django/middleware/common.py", line 74, in process_request
    if (not urlresolvers.is_valid_path(request.path_info, urlconf) and
  File "/home/parladaddy/parlasearch/venv/local/lib/python2.7/site-packages/django/core/urlresolvers.py", line 646, in is_valid_path
    resolve(path, urlconf)
  File "/home/parladaddy/parlasearch/venv/local/lib/python2.7/site-packages/django/core/urlresolvers.py", line 521, in resolve
    return get_resolver(urlconf).resolve(path)
  File "/home/parladaddy/parlasearch/venv/local/lib/python2.7/site-packages/django/core/urlresolvers.py", line 365, in resolve
    for pattern in self.url_patterns:
  File "/home/parladaddy/parlasearch/venv/local/lib/python2.7/site-packages/django/core/urlresolvers.py", line 401, in url_patterns
    patterns = getattr(self.urlconf_module, "urlpatterns", self.urlconf_module)
  File "/home/parladaddy/parlasearch/venv/local/lib/python2.7/site-packages/django/core/urlresolvers.py", line 395, in urlconf_module
    self._urlconf_module = import_module(self.urlconf_name)
  File "/usr/lib/python2.7/importlib/__init__.py", line 37, in import_module
    __import__(name)
  File "/home/parladaddy/parlasearch/parlasearch/urls.py", line 18, in <module>
    from searchapi.views import query
  File "/home/parladaddy/parlasearch/searchapi/views.py", line 50
    'fq': 'speaker_i:(' + people + ') OR party_i:(' + parties ')',
                                                                ^
SyntaxError: invalid syntax
Internal Server Error: /favicon.ico
Traceback (most recent call last):
  File "/home/parladaddy/parlasearch/venv/local/lib/python2.7/site-packages/django/core/handlers/base.py", line 108, in get_response
    response = middleware_method(request)
  File "/home/parladaddy/parlasearch/venv/local/lib/python2.7/site-packages/django/middleware/common.py", line 74, in process_request
    if (not urlresolvers.is_valid_path(request.path_info, urlconf) and
  File "/home/parladaddy/parlasearch/venv/local/lib/python2.7/site-packages/django/core/urlresolvers.py", line 646, in is_valid_path
    resolve(path, urlconf)
  File "/home/parladaddy/parlasearch/venv/local/lib/python2.7/site-packages/django/core/urlresolvers.py", line 521, in resolve
    return get_resolver(urlconf).resolve(path)
  File "/home/parladaddy/parlasearch/venv/local/lib/python2.7/site-packages/django/core/urlresolvers.py", line 365, in resolve
    for pattern in self.url_patterns:
  File "/home/parladaddy/parlasearch/venv/local/lib/python2.7/site-packages/django/core/urlresolvers.py", line 401, in url_patterns
    patterns = getattr(self.urlconf_module, "urlpatterns", self.urlconf_module)
  File "/home/parladaddy/parlasearch/venv/local/lib/python2.7/site-packages/django/core/urlresolvers.py", line 395, in urlconf_module
    self._urlconf_module = import_module(self.urlconf_name)
  File "/usr/lib/python2.7/importlib/__init__.py", line 37, in import_module
    __import__(name)
  File "/home/parladaddy/parlasearch/parlasearch/urls.py", line 18, in <module>
    from searchapi.views import query
  File "/home/parladaddy/parlasearch/searchapi/views.py", line 50
    'fq': 'speaker_i:(' + people + ') OR party_i:(' + parties ')',
                                                                ^
SyntaxError: invalid syntax
Internal Server Error: /filter/kriza/11 12/5 6 7
Traceback (most recent call last):
  File "/home/parladaddy/parlasearch/venv/local/lib/python2.7/site-packages/django/core/handlers/base.py", line 108, in get_response
    response = middleware_method(request)
  File "/home/parladaddy/parlasearch/venv/local/lib/python2.7/site-packages/django/middleware/common.py", line 74, in process_request
    if (not urlresolvers.is_valid_path(request.path_info, urlconf) and
  File "/home/parladaddy/parlasearch/venv/local/lib/python2.7/site-packages/django/core/urlresolvers.py", line 646, in is_valid_path
    resolve(path, urlconf)
  File "/home/parladaddy/parlasearch/venv/local/lib/python2.7/site-packages/django/core/urlresolvers.py", line 521, in resolve
    return get_resolver(urlconf).resolve(path)
  File "/home/parladaddy/parlasearch/venv/local/lib/python2.7/site-packages/django/core/urlresolvers.py", line 365, in resolve
    for pattern in self.url_patterns:
  File "/home/parladaddy/parlasearch/venv/local/lib/python2.7/site-packages/django/core/urlresolvers.py", line 401, in url_patterns
    patterns = getattr(self.urlconf_module, "urlpatterns", self.urlconf_module)
  File "/home/parladaddy/parlasearch/venv/local/lib/python2.7/site-packages/django/core/urlresolvers.py", line 395, in urlconf_module
    self._urlconf_module = import_module(self.urlconf_name)
  File "/usr/lib/python2.7/importlib/__init__.py", line 37, in import_module
    __import__(name)
  File "/home/parladaddy/parlasearch/parlasearch/urls.py", line 18, in <module>
    from searchapi.views import query
ImportError: cannot import name query
Internal Server Error: /favicon.ico
Traceback (most recent call last):
  File "/home/parladaddy/parlasearch/venv/local/lib/python2.7/site-packages/django/core/handlers/base.py", line 108, in get_response
    response = middleware_method(request)
  File "/home/parladaddy/parlasearch/venv/local/lib/python2.7/site-packages/django/middleware/common.py", line 74, in process_request
    if (not urlresolvers.is_valid_path(request.path_info, urlconf) and
  File "/home/parladaddy/parlasearch/venv/local/lib/python2.7/site-packages/django/core/urlresolvers.py", line 646, in is_valid_path
    resolve(path, urlconf)
  File "/home/parladaddy/parlasearch/venv/local/lib/python2.7/site-packages/django/core/urlresolvers.py", line 521, in resolve
    return get_resolver(urlconf).resolve(path)
  File "/home/parladaddy/parlasearch/venv/local/lib/python2.7/site-packages/django/core/urlresolvers.py", line 365, in resolve
    for pattern in self.url_patterns:
  File "/home/parladaddy/parlasearch/venv/local/lib/python2.7/site-packages/django/core/urlresolvers.py", line 401, in url_patterns
    patterns = getattr(self.urlconf_module, "urlpatterns", self.urlconf_module)
  File "/home/parladaddy/parlasearch/venv/local/lib/python2.7/site-packages/django/core/urlresolvers.py", line 395, in urlconf_module
    self._urlconf_module = import_module(self.urlconf_name)
  File "/usr/lib/python2.7/importlib/__init__.py", line 37, in import_module
    __import__(name)
  File "/home/parladaddy/parlasearch/parlasearch/urls.py", line 18, in <module>
    from searchapi.views import query
ImportError: cannot import name query
Internal Server Error: /filter/kriza/11 12/
Traceback (most recent call last):
  File "/home/parladaddy/parlasearch/venv/local/lib/python2.7/site-packages/django/core/handlers/base.py", line 119, in get_response
    resolver_match = resolver.resolve(request.path_info)
  File "/home/parladaddy/parlasearch/venv/local/lib/python2.7/site-packages/django/core/urlresolvers.py", line 365, in resolve
    for pattern in self.url_patterns:
  File "/home/parladaddy/parlasearch/venv/local/lib/python2.7/site-packages/django/core/urlresolvers.py", line 401, in url_patterns
    patterns = getattr(self.urlconf_module, "urlpatterns", self.urlconf_module)
  File "/home/parladaddy/parlasearch/venv/local/lib/python2.7/site-packages/django/core/urlresolvers.py", line 395, in urlconf_module
    self._urlconf_module = import_module(self.urlconf_name)
  File "/usr/lib/python2.7/importlib/__init__.py", line 37, in import_module
    __import__(name)
  File "/home/parladaddy/parlasearch/parlasearch/urls.py", line 18, in <module>
    from searchapi.views import regularQuery, filterQuery
  File "/home/parladaddy/parlasearch/searchapi/views.py", line 74
    
    ^
IndentationError: expected an indented block
Internal Server Error: /favicon.ico
Traceback (most recent call last):
  File "/home/parladaddy/parlasearch/venv/local/lib/python2.7/site-packages/django/core/handlers/base.py", line 108, in get_response
    response = middleware_method(request)
  File "/home/parladaddy/parlasearch/venv/local/lib/python2.7/site-packages/django/middleware/common.py", line 74, in process_request
    if (not urlresolvers.is_valid_path(request.path_info, urlconf) and
  File "/home/parladaddy/parlasearch/venv/local/lib/python2.7/site-packages/django/core/urlresolvers.py", line 646, in is_valid_path
    resolve(path, urlconf)
  File "/home/parladaddy/parlasearch/venv/local/lib/python2.7/site-packages/django/core/urlresolvers.py", line 521, in resolve
    return get_resolver(urlconf).resolve(path)
  File "/home/parladaddy/parlasearch/venv/local/lib/python2.7/site-packages/django/core/urlresolvers.py", line 365, in resolve
    for pattern in self.url_patterns:
  File "/home/parladaddy/parlasearch/venv/local/lib/python2.7/site-packages/django/core/urlresolvers.py", line 401, in url_patterns
    patterns = getattr(self.urlconf_module, "urlpatterns", self.urlconf_module)
  File "/home/parladaddy/parlasearch/venv/local/lib/python2.7/site-packages/django/core/urlresolvers.py", line 395, in urlconf_module
    self._urlconf_module = import_module(self.urlconf_name)
  File "/usr/lib/python2.7/importlib/__init__.py", line 37, in import_module
    __import__(name)
  File "/home/parladaddy/parlasearch/parlasearch/urls.py", line 18, in <module>
    from searchapi.views import regularQuery, filterQuery
  File "/home/parladaddy/parlasearch/searchapi/views.py", line 74
    
    ^
IndentationError: expected an indented block
Not Found: /filter/posast//97
Not Found: /favicon.ico
Not Found: /filter/kriza//97
Internal Server Error: /filter/kriza
Traceback (most recent call last):
  File "/home/parladaddy/parlasearch/venv/local/lib/python2.7/site-packages/django/core/handlers/base.py", line 132, in get_response
    response = wrapped_callback(request, *callback_args, **callback_kwargs)
TypeError: filterQuery() takes at least 3 arguments (2 given)
Internal Server Error: /filter/kriza
Traceback (most recent call last):
  File "/home/parladaddy/parlasearch/venv/local/lib/python2.7/site-packages/django/core/handlers/base.py", line 132, in get_response
    response = wrapped_callback(request, *callback_args, **callback_kwargs)
  File "/home/parladaddy/parlasearch/searchapi/views.py", line 51, in filterQuery
    'fq': 'speaker_i:(' + people + ') OR party_i:(' + parties + ')',
TypeError: cannot concatenate 'str' and 'NoneType' objects
Internal Server Error: /mlt/1234
Traceback (most recent call last):
  File "/home/parladaddy/parlasearch/venv/local/lib/python2.7/site-packages/django/core/handlers/base.py", line 108, in get_response
    response = middleware_method(request)
  File "/home/parladaddy/parlasearch/venv/local/lib/python2.7/site-packages/django/middleware/common.py", line 74, in process_request
    if (not urlresolvers.is_valid_path(request.path_info, urlconf) and
  File "/home/parladaddy/parlasearch/venv/local/lib/python2.7/site-packages/django/core/urlresolvers.py", line 646, in is_valid_path
    resolve(path, urlconf)
  File "/home/parladaddy/parlasearch/venv/local/lib/python2.7/site-packages/django/core/urlresolvers.py", line 521, in resolve
    return get_resolver(urlconf).resolve(path)
  File "/home/parladaddy/parlasearch/venv/local/lib/python2.7/site-packages/django/core/urlresolvers.py", line 365, in resolve
    for pattern in self.url_patterns:
  File "/home/parladaddy/parlasearch/venv/local/lib/python2.7/site-packages/django/core/urlresolvers.py", line 401, in url_patterns
    patterns = getattr(self.urlconf_module, "urlpatterns", self.urlconf_module)
  File "/home/parladaddy/parlasearch/venv/local/lib/python2.7/site-packages/django/core/urlresolvers.py", line 395, in urlconf_module
    self._urlconf_module = import_module(self.urlconf_name)
  File "/usr/lib/python2.7/importlib/__init__.py", line 37, in import_module
    __import__(name)
  File "/home/parladaddy/parlasearch/parlasearch/urls.py", line 23, in <module>
    url(r'^mlt/(?P<speech_i>[0-9]+)', mltQuery),
NameError: name 'mltQuery' is not defined
Internal Server Error: /mlt/1234
Traceback (most recent call last):
  File "/home/parladaddy/parlasearch/venv/local/lib/python2.7/site-packages/django/core/handlers/base.py", line 108, in get_response
    response = middleware_method(request)
  File "/home/parladaddy/parlasearch/venv/local/lib/python2.7/site-packages/django/middleware/common.py", line 74, in process_request
    if (not urlresolvers.is_valid_path(request.path_info, urlconf) and
  File "/home/parladaddy/parlasearch/venv/local/lib/python2.7/site-packages/django/core/urlresolvers.py", line 646, in is_valid_path
    resolve(path, urlconf)
  File "/home/parladaddy/parlasearch/venv/local/lib/python2.7/site-packages/django/core/urlresolvers.py", line 521, in resolve
    return get_resolver(urlconf).resolve(path)
  File "/home/parladaddy/parlasearch/venv/local/lib/python2.7/site-packages/django/core/urlresolvers.py", line 365, in resolve
    for pattern in self.url_patterns:
  File "/home/parladaddy/parlasearch/venv/local/lib/python2.7/site-packages/django/core/urlresolvers.py", line 401, in url_patterns
    patterns = getattr(self.urlconf_module, "urlpatterns", self.urlconf_module)
  File "/home/parladaddy/parlasearch/venv/local/lib/python2.7/site-packages/django/core/urlresolvers.py", line 395, in urlconf_module
    self._urlconf_module = import_module(self.urlconf_name)
  File "/usr/lib/python2.7/importlib/__init__.py", line 37, in import_module
    __import__(name)
  File "/home/parladaddy/parlasearch/parlasearch/urls.py", line 23, in <module>
    url(r'^mlt/(?P<speech_i>[0-9]+)', mltQuery),
NameError: name 'mltQuery' is not defined
Internal Server Error: /mlt/1234
Traceback (most recent call last):
  File "/home/parladaddy/parlasearch/venv/local/lib/python2.7/site-packages/django/core/handlers/base.py", line 132, in get_response
    response = wrapped_callback(request, *callback_args, **callback_kwargs)
  File "/home/parladaddy/parlasearch/searchapi/views.py", line 88, in mltQuery
    r = requests.get(url)
NameError: global name 'url' is not defined
Internal Server Error: /mlt/1234
Traceback (most recent call last):
  File "/home/parladaddy/parlasearch/venv/local/lib/python2.7/site-packages/django/core/handlers/base.py", line 132, in get_response
    response = wrapped_callback(request, *callback_args, **callback_kwargs)
  File "/home/parladaddy/parlasearch/searchapi/views.py", line 88, in mltQuery
    r = requests.get(url)
NameError: global name 'url' is not defined
Internal Server Error: /mlt/1234
Traceback (most recent call last):
  File "/home/parladaddy/parlasearch/venv/local/lib/python2.7/site-packages/django/core/handlers/base.py", line 132, in get_response
    response = wrapped_callback(request, *callback_args, **callback_kwargs)
  File "/home/parladaddy/parlasearch/searchapi/views.py", line 90, in mltQuery
    return JsonResponse(r.json())
  File "/home/parladaddy/parlasearch/venv/local/lib/python2.7/site-packages/requests/models.py", line 805, in json
    return complexjson.loads(self.text, **kwargs)
  File "/usr/lib/python2.7/json/__init__.py", line 338, in loads
    return _default_decoder.decode(s)
  File "/usr/lib/python2.7/json/decoder.py", line 366, in decode
    obj, end = self.raw_decode(s, idx=_w(s, 0).end())
  File "/usr/lib/python2.7/json/decoder.py", line 384, in raw_decode
    raise ValueError("No JSON object could be decoded")
ValueError: No JSON object could be decoded
Not Found: /favicon.ico
Not Found: /filter/
Not Found: /vecina
Not Found: /filter/"(Za je glasovalo" je
Not Found: /begunci
Not Found: /favicon.ico
Not Found: /osamosvojitev
Not Found: /favicon.ico
Not Found: /
Not Found: /favicon.ico
Not Found: /smoke
Not Found: /
Not Found: /
Not Found: /
Not Found: /osamosvojitev
Not Found: /
Not Found: /^qsfkoafs
Not Found: /
Not Found: /favicon.ico
Not Found: /favicon.ico
Not Found: /filter/
Not Found: /filter
Not Found: /q=safas
Not Found: /favicon.ico
Not Found: /q/šolstvo
Not Found: /q/šolstvo
Not Found: /favicon.ico
Not Found: /favicon.ico
Internal Server Error: /q/voda
Traceback (most recent call last):
  File "/home/parladaddy/parlasearch/venv/local/lib/python2.7/site-packages/django/core/handlers/base.py", line 108, in get_response
    response = middleware_method(request)
  File "/home/parladaddy/parlasearch/venv/local/lib/python2.7/site-packages/django/middleware/common.py", line 74, in process_request
    if (not urlresolvers.is_valid_path(request.path_info, urlconf) and
  File "/home/parladaddy/parlasearch/venv/local/lib/python2.7/site-packages/django/core/urlresolvers.py", line 646, in is_valid_path
    resolve(path, urlconf)
  File "/home/parladaddy/parlasearch/venv/local/lib/python2.7/site-packages/django/core/urlresolvers.py", line 521, in resolve
    return get_resolver(urlconf).resolve(path)
  File "/home/parladaddy/parlasearch/venv/local/lib/python2.7/site-packages/django/core/urlresolvers.py", line 365, in resolve
    for pattern in self.url_patterns:
  File "/home/parladaddy/parlasearch/venv/local/lib/python2.7/site-packages/django/core/urlresolvers.py", line 401, in url_patterns
    patterns = getattr(self.urlconf_module, "urlpatterns", self.urlconf_module)
  File "/home/parladaddy/parlasearch/venv/local/lib/python2.7/site-packages/django/core/urlresolvers.py", line 395, in urlconf_module
    self._urlconf_module = import_module(self.urlconf_name)
  File "/usr/lib/python2.7/importlib/__init__.py", line 37, in import_module
    __import__(name)
  File "/home/parladaddy/parlasearch/parlasearch/urls.py", line 18, in <module>
    from searchapi.views import regularQuery, filterQuery, mltQuery
  File "/home/parladaddy/parlasearch/searchapi/views.py", line 17
    'facet.date': 'datetime_dt',
                ^
SyntaxError: invalid syntax
Internal Server Error: /favicon.ico
Traceback (most recent call last):
  File "/home/parladaddy/parlasearch/venv/local/lib/python2.7/site-packages/django/core/handlers/base.py", line 108, in get_response
    response = middleware_method(request)
  File "/home/parladaddy/parlasearch/venv/local/lib/python2.7/site-packages/django/middleware/common.py", line 74, in process_request
    if (not urlresolvers.is_valid_path(request.path_info, urlconf) and
  File "/home/parladaddy/parlasearch/venv/local/lib/python2.7/site-packages/django/core/urlresolvers.py", line 646, in is_valid_path
    resolve(path, urlconf)
  File "/home/parladaddy/parlasearch/venv/local/lib/python2.7/site-packages/django/core/urlresolvers.py", line 521, in resolve
    return get_resolver(urlconf).resolve(path)
  File "/home/parladaddy/parlasearch/venv/local/lib/python2.7/site-packages/django/core/urlresolvers.py", line 365, in resolve
    for pattern in self.url_patterns:
  File "/home/parladaddy/parlasearch/venv/local/lib/python2.7/site-packages/django/core/urlresolvers.py", line 401, in url_patterns
    patterns = getattr(self.urlconf_module, "urlpatterns", self.urlconf_module)
  File "/home/parladaddy/parlasearch/venv/local/lib/python2.7/site-packages/django/core/urlresolvers.py", line 395, in urlconf_module
    self._urlconf_module = import_module(self.urlconf_name)
  File "/usr/lib/python2.7/importlib/__init__.py", line 37, in import_module
    __import__(name)
  File "/home/parladaddy/parlasearch/parlasearch/urls.py", line 18, in <module>
    from searchapi.views import regularQuery, filterQuery, mltQuery
  File "/home/parladaddy/parlasearch/searchapi/views.py", line 17
    'facet.date': 'datetime_dt',
                ^
SyntaxError: invalid syntax
Internal Server Error: /q/slovenija
Traceback (most recent call last):
  File "/home/parladaddy/parlasearch/venv/local/lib/python2.7/site-packages/django/core/handlers/base.py", line 108, in get_response
    response = middleware_method(request)
  File "/home/parladaddy/parlasearch/venv/local/lib/python2.7/site-packages/django/middleware/common.py", line 74, in process_request
    if (not urlresolvers.is_valid_path(request.path_info, urlconf) and
  File "/home/parladaddy/parlasearch/venv/local/lib/python2.7/site-packages/django/core/urlresolvers.py", line 646, in is_valid_path
    resolve(path, urlconf)
  File "/home/parladaddy/parlasearch/venv/local/lib/python2.7/site-packages/django/core/urlresolvers.py", line 521, in resolve
    return get_resolver(urlconf).resolve(path)
  File "/home/parladaddy/parlasearch/venv/local/lib/python2.7/site-packages/django/core/urlresolvers.py", line 365, in resolve
    for pattern in self.url_patterns:
  File "/home/parladaddy/parlasearch/venv/local/lib/python2.7/site-packages/django/core/urlresolvers.py", line 401, in url_patterns
    patterns = getattr(self.urlconf_module, "urlpatterns", self.urlconf_module)
  File "/home/parladaddy/parlasearch/venv/local/lib/python2.7/site-packages/django/core/urlresolvers.py", line 395, in urlconf_module
    self._urlconf_module = import_module(self.urlconf_name)
  File "/usr/lib/python2.7/importlib/__init__.py", line 37, in import_module
    __import__(name)
  File "/home/parladaddy/parlasearch/parlasearch/urls.py", line 18, in <module>
    from searchapi.views import regularQuery, filterQuery, mltQuery
  File "/home/parladaddy/parlasearch/searchapi/views.py", line 17
    'facet.date': 'datetime_dt',
                ^
SyntaxError: invalid syntax
Not Found: /favicon.ico
Not Found: /favicon.ico
Not Found: /favicon.ico
Not Found: /robots.txt
Not Found: /konoplja
Not Found: /favicon.ico
Not Found: /favicon.ico
Not Found: /favicon.ico
Not Found: /favicon.ico
Not Found: /robots.txt
Not Found: /favicon.ico
Not Found: /favicon.ico
Not Found: /q/žica
Not Found: /favicon.ico
Not Found: /favicon.ico
Not Found: /favicon.ico
Not Found: /favicon.ico
Not Found: /
Not Found: /favicon.ico
Not Found: /favicon.ico
Not Found: /favicon.ico
Not Found: /favicon.ico
Not Found: /favicon.ico
Not Found: /favicon.ico
Not Found: /favicon.ico
Not Found: /favicon.ico
Not Found: /favicon.ico
Not Found: /favicon.ico
Bad Request (UnicodeDecodeError)
Traceback (most recent call last):
  File "/home/parladaddy/parlasearch/venv/local/lib/python2.7/site-packages/django/core/handlers/wsgi.py", line 179, in __call__
    request = self.request_class(environ)
  File "/home/parladaddy/parlasearch/venv/local/lib/python2.7/site-packages/django/core/handlers/wsgi.py", line 84, in __init__
    path_info = get_path_info(environ)
  File "/home/parladaddy/parlasearch/venv/local/lib/python2.7/site-packages/django/core/handlers/wsgi.py", line 209, in get_path_info
    return path_info.decode(UTF_8)
  File "/home/parladaddy/parlasearch/venv/lib/python2.7/encodings/utf_8.py", line 16, in decode
    return codecs.utf_8_decode(input, errors, True)
UnicodeDecodeError: 'utf8' codec can't decode byte 0x9e in position 8: invalid start byte
Bad Request (UnicodeDecodeError)
Traceback (most recent call last):
  File "/home/parladaddy/parlasearch/venv/local/lib/python2.7/site-packages/django/core/handlers/wsgi.py", line 179, in __call__
    request = self.request_class(environ)
  File "/home/parladaddy/parlasearch/venv/local/lib/python2.7/site-packages/django/core/handlers/wsgi.py", line 84, in __init__
    path_info = get_path_info(environ)
  File "/home/parladaddy/parlasearch/venv/local/lib/python2.7/site-packages/django/core/handlers/wsgi.py", line 209, in get_path_info
    return path_info.decode(UTF_8)
  File "/home/parladaddy/parlasearch/venv/lib/python2.7/encodings/utf_8.py", line 16, in decode
    return codecs.utf_8_decode(input, errors, True)
UnicodeDecodeError: 'utf8' codec can't decode byte 0x9e in position 8: invalid start byte
Not Found: /
Not Found: /
Not Found: /
Not Found: /
Not Found: /
Not Found: /
Not Found: /
Not Found: /
Not Found: /
Not Found: /
Not Found: /
Not Found: /favicon.ico
Not Found: /favicon.ico
Not Found: /
Not Found: /
Not Found: /
Not Found: /favicon.ico
Not Found: /
Not Found: /
Not Found: /
Not Found: /favicon.ico
Not Found: /favicon.ico
Not Found: /
Not Found: /favicon.ico
Not Found: /favicon.ico
Not Found: /favicon.ico
Not Found: /favicon.ico
Not Found: /favicon.ico
Internal Server Error: /q/gamad
Traceback (most recent call last):
  File "/home/parladaddy/parlasearch/venv/local/lib/python2.7/site-packages/django/core/handlers/base.py", line 132, in get_response
    response = wrapped_callback(request, *callback_args, **callback_kwargs)
  File "/home/parladaddy/parlasearch/searchapi/views.py", line 54, in regularQuery
    return JsonResponse(enrichQuery(r.json()))
  File "/home/parladaddy/parlasearch/searchapi/utils.py", line 12, in enrichQuery
    data['facet_counts']['facet_fields']['speaker_i'][i] = {'person': requests.get('https://analize.parlameter.si/v1/utils/getPersonData/82').json(), 'result': data['facet_counts']['facet_fields']['speaker_i'][i] + 1}
TypeError: coercing to Unicode: need string or buffer, int found
Internal Server Error: /q/gamad
Traceback (most recent call last):
  File "/home/parladaddy/parlasearch/venv/local/lib/python2.7/site-packages/django/core/handlers/base.py", line 132, in get_response
    response = wrapped_callback(request, *callback_args, **callback_kwargs)
  File "/home/parladaddy/parlasearch/searchapi/views.py", line 54, in regularQuery
    return JsonResponse(enrichQuery(r.json()))
  File "/home/parladaddy/parlasearch/searchapi/utils.py", line 12, in enrichQuery
    data['facet_counts']['facet_fields']['speaker_i'][i] = {'person': requests.get('https://analize.parlameter.si/v1/utils/getPersonData/82').json(), 'result': str(data['facet_counts']['facet_fields']['speaker_i'][i] + 1)}
TypeError: coercing to Unicode: need string or buffer, int found
Internal Server Error: /q/gamad
Traceback (most recent call last):
  File "/home/parladaddy/parlasearch/venv/local/lib/python2.7/site-packages/django/core/handlers/base.py", line 132, in get_response
    response = wrapped_callback(request, *callback_args, **callback_kwargs)
  File "/home/parladaddy/parlasearch/searchapi/views.py", line 54, in regularQuery
    return JsonResponse(enrichQuery(r.json()))
  File "/home/parladaddy/parlasearch/searchapi/utils.py", line 14, in enrichQuery
    data['facet_counts']['facet_fields']['speaker_i'][i].pop()
AttributeError: 'int' object has no attribute 'pop'
Internal Server Error: /q/gamad
Traceback (most recent call last):
  File "/home/parladaddy/parlasearch/venv/local/lib/python2.7/site-packages/django/core/handlers/base.py", line 108, in get_response
    response = middleware_method(request)
  File "/home/parladaddy/parlasearch/venv/local/lib/python2.7/site-packages/django/middleware/common.py", line 74, in process_request
    if (not urlresolvers.is_valid_path(request.path_info, urlconf) and
  File "/home/parladaddy/parlasearch/venv/local/lib/python2.7/site-packages/django/core/urlresolvers.py", line 646, in is_valid_path
    resolve(path, urlconf)
  File "/home/parladaddy/parlasearch/venv/local/lib/python2.7/site-packages/django/core/urlresolvers.py", line 521, in resolve
    return get_resolver(urlconf).resolve(path)
  File "/home/parladaddy/parlasearch/venv/local/lib/python2.7/site-packages/django/core/urlresolvers.py", line 365, in resolve
    for pattern in self.url_patterns:
  File "/home/parladaddy/parlasearch/venv/local/lib/python2.7/site-packages/django/core/urlresolvers.py", line 401, in url_patterns
    patterns = getattr(self.urlconf_module, "urlpatterns", self.urlconf_module)
  File "/home/parladaddy/parlasearch/venv/local/lib/python2.7/site-packages/django/core/urlresolvers.py", line 395, in urlconf_module
    self._urlconf_module = import_module(self.urlconf_name)
  File "/usr/lib/python2.7/importlib/__init__.py", line 37, in import_module
    __import__(name)
  File "/home/parladaddy/parlasearch/parlasearch/urls.py", line 18, in <module>
    from searchapi.views import regularQuery, filterQuery, mltQuery
  File "/home/parladaddy/parlasearch/searchapi/views.py", line 5, in <module>
    from utils import enrichQuery
  File "/home/parladaddy/parlasearch/searchapi/utils.py", line 14
    del data['facet_counts']['facet_fields']['speaker_i'].pop(i)
SyntaxError: can't delete function call
Internal Server Error: /q/gamad
Traceback (most recent call last):
  File "/home/parladaddy/parlasearch/venv/local/lib/python2.7/site-packages/django/core/handlers/base.py", line 108, in get_response
    response = middleware_method(request)
  File "/home/parladaddy/parlasearch/venv/local/lib/python2.7/site-packages/django/middleware/common.py", line 74, in process_request
    if (not urlresolvers.is_valid_path(request.path_info, urlconf) and
  File "/home/parladaddy/parlasearch/venv/local/lib/python2.7/site-packages/django/core/urlresolvers.py", line 646, in is_valid_path
    resolve(path, urlconf)
  File "/home/parladaddy/parlasearch/venv/local/lib/python2.7/site-packages/django/core/urlresolvers.py", line 521, in resolve
    return get_resolver(urlconf).resolve(path)
  File "/home/parladaddy/parlasearch/venv/local/lib/python2.7/site-packages/django/core/urlresolvers.py", line 365, in resolve
    for pattern in self.url_patterns:
  File "/home/parladaddy/parlasearch/venv/local/lib/python2.7/site-packages/django/core/urlresolvers.py", line 401, in url_patterns
    patterns = getattr(self.urlconf_module, "urlpatterns", self.urlconf_module)
  File "/home/parladaddy/parlasearch/venv/local/lib/python2.7/site-packages/django/core/urlresolvers.py", line 395, in urlconf_module
    self._urlconf_module = import_module(self.urlconf_name)
  File "/usr/lib/python2.7/importlib/__init__.py", line 37, in import_module
    __import__(name)
  File "/home/parladaddy/parlasearch/parlasearch/urls.py", line 18, in <module>
    from searchapi.views import regularQuery, filterQuery, mltQuery
  File "/home/parladaddy/parlasearch/searchapi/views.py", line 5, in <module>
    from utils import enrichQuery
  File "/home/parladaddy/parlasearch/searchapi/utils.py", line 19
    for data['facet_counts']['facet_fields']['speaker_i'] = results
                                                          ^
SyntaxError: invalid syntax
Internal Server Error: /q/gamad
Traceback (most recent call last):
  File "/home/parladaddy/parlasearch/venv/local/lib/python2.7/site-packages/django/core/handlers/base.py", line 132, in get_response
    response = wrapped_callback(request, *callback_args, **callback_kwargs)
  File "/home/parladaddy/parlasearch/searchapi/views.py", line 54, in regularQuery
    return JsonResponse(enrichQuery(r.json()))
  File "/home/parladaddy/parlasearch/searchapi/utils.py", line 14, in enrichQuery
    results.append({'person': requests.get('https://analize.parlameter.si/v1/utils/getPersonData/' + str(i)).json(), 'score': str(data['facet_counts']['facet_fields']['speaker_i'][i + 1])})
  File "/home/parladaddy/parlasearch/venv/local/lib/python2.7/site-packages/requests/models.py", line 805, in json
    return complexjson.loads(self.text, **kwargs)
  File "/usr/lib/python2.7/json/__init__.py", line 338, in loads
    return _default_decoder.decode(s)
  File "/usr/lib/python2.7/json/decoder.py", line 366, in decode
    obj, end = self.raw_decode(s, idx=_w(s, 0).end())
  File "/usr/lib/python2.7/json/decoder.py", line 384, in raw_decode
    raise ValueError("No JSON object could be decoded")
ValueError: No JSON object could be decoded
Internal Server Error: /q/gamad
Traceback (most recent call last):
  File "/home/parladaddy/parlasearch/venv/local/lib/python2.7/site-packages/django/core/handlers/base.py", line 132, in get_response
    response = wrapped_callback(request, *callback_args, **callback_kwargs)
  File "/home/parladaddy/parlasearch/searchapi/views.py", line 54, in regularQuery
    return JsonResponse(enrichQuery(r.json()))
  File "/home/parladaddy/parlasearch/searchapi/utils.py", line 14, in enrichQuery
    results.append({'person': requests.get('https://analize.parlameter.si/v1/utils/getPersonData/' + i).json(), 'score': str(data['facet_counts']['facet_fields']['speaker_i'][i + 1])})
TypeError: cannot concatenate 'str' and 'int' objects
Internal Server Error: /q/gamad
Traceback (most recent call last):
  File "/home/parladaddy/parlasearch/venv/local/lib/python2.7/site-packages/django/core/handlers/base.py", line 132, in get_response
    response = wrapped_callback(request, *callback_args, **callback_kwargs)
  File "/home/parladaddy/parlasearch/searchapi/views.py", line 54, in regularQuery
    return JsonResponse(enrichQuery(r.json()))
  File "/home/parladaddy/parlasearch/searchapi/utils.py", line 14, in enrichQuery
    results.append({'person': requests.get('https://analize.parlameter.si/v1/utils/getPersonData/' + str(i)).json(), 'score': str(data['facet_counts']['facet_fields']['speaker_i'][i + 1])})
  File "/home/parladaddy/parlasearch/venv/local/lib/python2.7/site-packages/requests/models.py", line 805, in json
    return complexjson.loads(self.text, **kwargs)
  File "/usr/lib/python2.7/json/__init__.py", line 338, in loads
    return _default_decoder.decode(s)
  File "/usr/lib/python2.7/json/decoder.py", line 366, in decode
    obj, end = self.raw_decode(s, idx=_w(s, 0).end())
  File "/usr/lib/python2.7/json/decoder.py", line 384, in raw_decode
    raise ValueError("No JSON object could be decoded")
ValueError: No JSON object could be decoded
Internal Server Error: /q/gamad
Traceback (most recent call last):
  File "/home/parladaddy/parlasearch/venv/local/lib/python2.7/site-packages/django/core/handlers/base.py", line 132, in get_response
    response = wrapped_callback(request, *callback_args, **callback_kwargs)
  File "/home/parladaddy/parlasearch/searchapi/views.py", line 54, in regularQuery
    return JsonResponse(enrichQuery(r.json()))
  File "/home/parladaddy/parlasearch/searchapi/utils.py", line 14, in enrichQuery
    results.append({'person': requests.get('https://analize.parlameter.si/v1/utils/getPersonData/' + str(i)).json(), 'score': str(data['facet_counts']['facet_fields']['speaker_i'][i + 1])})
  File "/home/parladaddy/parlasearch/venv/local/lib/python2.7/site-packages/requests/models.py", line 805, in json
    return complexjson.loads(self.text, **kwargs)
  File "/usr/lib/python2.7/json/__init__.py", line 338, in loads
    return _default_decoder.decode(s)
  File "/usr/lib/python2.7/json/decoder.py", line 366, in decode
    obj, end = self.raw_decode(s, idx=_w(s, 0).end())
  File "/usr/lib/python2.7/json/decoder.py", line 384, in raw_decode
    raise ValueError("No JSON object could be decoded")
ValueError: No JSON object could be decoded
Internal Server Error: /q/gamad
Traceback (most recent call last):
  File "/home/parladaddy/parlasearch/venv/local/lib/python2.7/site-packages/django/core/handlers/base.py", line 132, in get_response
    response = wrapped_callback(request, *callback_args, **callback_kwargs)
  File "/home/parladaddy/parlasearch/searchapi/views.py", line 54, in regularQuery
    return JsonResponse(enrichQuery(r.json()))
  File "/home/parladaddy/parlasearch/searchapi/utils.py", line 14, in enrichQuery
    results.append({'person': requests.get('https://analize.parlameter.si/v1/utils/getPersonData/' + str(i)).json(), 'score': str(data['facet_counts']['facet_fields']['speaker_i'][i + 1])})
  File "/home/parladaddy/parlasearch/venv/local/lib/python2.7/site-packages/requests/models.py", line 805, in json
    return complexjson.loads(self.text, **kwargs)
  File "/usr/lib/python2.7/json/__init__.py", line 338, in loads
    return _default_decoder.decode(s)
  File "/usr/lib/python2.7/json/decoder.py", line 366, in decode
    obj, end = self.raw_decode(s, idx=_w(s, 0).end())
  File "/usr/lib/python2.7/json/decoder.py", line 384, in raw_decode
    raise ValueError("No JSON object could be decoded")
ValueError: No JSON object could be decoded
Internal Server Error: /q/gamad
Traceback (most recent call last):
  File "/home/parladaddy/parlasearch/venv/local/lib/python2.7/site-packages/django/core/handlers/base.py", line 132, in get_response
    response = wrapped_callback(request, *callback_args, **callback_kwargs)
  File "/home/parladaddy/parlasearch/searchapi/views.py", line 54, in regularQuery
    return JsonResponse(enrichQuery(r.json()))
  File "/home/parladaddy/parlasearch/searchapi/utils.py", line 14, in enrichQuery
    results.append({'person': requests.get('https://analize.parlameter.si/v1/utils/getPersonData/' + str(i)).json(), 'score': str(data['facet_counts']['facet_fields']['speaker_i'][i + 1])})
  File "/home/parladaddy/parlasearch/venv/local/lib/python2.7/site-packages/requests/models.py", line 805, in json
    return complexjson.loads(self.text, **kwargs)
  File "/usr/lib/python2.7/json/__init__.py", line 338, in loads
    return _default_decoder.decode(s)
  File "/usr/lib/python2.7/json/decoder.py", line 366, in decode
    obj, end = self.raw_decode(s, idx=_w(s, 0).end())
  File "/usr/lib/python2.7/json/decoder.py", line 384, in raw_decode
    raise ValueError("No JSON object could be decoded")
ValueError: No JSON object could be decoded
Internal Server Error: /q/gamad
Traceback (most recent call last):
  File "/home/parladaddy/parlasearch/venv/local/lib/python2.7/site-packages/django/core/handlers/base.py", line 132, in get_response
    response = wrapped_callback(request, *callback_args, **callback_kwargs)
  File "/home/parladaddy/parlasearch/searchapi/views.py", line 54, in regularQuery
    return JsonResponse(enrichQuery(r.json()))
  File "/home/parladaddy/parlasearch/searchapi/utils.py", line 15, in enrichQuery
    results.append({'person': requests.get('https://analize.parlameter.si/v1/utils/getPersonData/' + parladata_id).json(), 'score': str(data['facet_counts']['facet_fields']['speaker_i'][i + 1])})
  File "/home/parladaddy/parlasearch/venv/local/lib/python2.7/site-packages/requests/models.py", line 805, in json
    return complexjson.loads(self.text, **kwargs)
  File "/usr/lib/python2.7/json/__init__.py", line 338, in loads
    return _default_decoder.decode(s)
  File "/usr/lib/python2.7/json/decoder.py", line 366, in decode
    obj, end = self.raw_decode(s, idx=_w(s, 0).end())
  File "/usr/lib/python2.7/json/decoder.py", line 384, in raw_decode
    raise ValueError("No JSON object could be decoded")
ValueError: No JSON object could be decoded
